<?xml version="1.0" ?>
<!-- =================================================================================== -->
<!-- |    This document was autogenerated by xacro from summit_xl_gen_j2n6s300_intel_d455_v2.urdf.xacro | -->
<!-- |    EDITING THIS FILE BY HAND IS NOT RECOMMENDED                                 | -->
<!-- =================================================================================== -->
<robot name="summit_xl" xmlns:body="http://playerstage.sourceforge.net/gazebo/xmlschema/#body" xmlns:controller="http://playerstage.sourceforge.net/gazebo/xmlschema/#controller" xmlns:gazebo="http://playerstage.sourceforge.net/gazebo/xmlschema/#gz" xmlns:geom="http://playerstage.sourceforge.net/gazebo/xmlschema/#geom" xmlns:interface="http://playerstage.sourceforge.net/gazebo/xmlschema/#interface" xmlns:joint="http://playerstage.sourceforge.net/gazebo/xmlschema/#joint" xmlns:model="http://playerstage.sourceforge.net/gazebo/xmlschema/#model" xmlns:physics="http://playerstage.sourceforge.net/gazebo/xmlschema/#physics" xmlns:renderable="http://playerstage.sourceforge.net/gazebo/xmlschema/#renderable" xmlns:rendering="http://playerstage.sourceforge.net/gazebo/xmlschema/#rendering" xmlns:sensor="http://playerstage.sourceforge.net/gazebo/xmlschema/#sensor" xmlns:xi="http://www.w3.org/2001/XInclude">
  <!-- ***************** -->
  <!-- Imported elements -->
  <!-- ***************** -->
  <!-- First we import all posible elements defined in the urdf.xacro files. All these elements are defined as macro:xacros -->
  <gazebo reference="base_footprint">
    <material>Gazebo/Green</material>
  </gazebo>
  <!-- in kg-->
  <!-- in kg-->
  <!-- source en.wikipedia.org/wiki/List_of_moments_of_inertia-->
  <!-- This file unifies all sensors that can be used on simulation, defined as xacro:macros -->
  <!-- <xacro:macro name="sensor_ultrasonic_a21_gazebo">
    <gazebo reference="${prefix}_link">
			<xacro:if value="${gpu}">
        <xacro:property name="ray_type" value="gpu_ray" />
        <xacro:property name="plugin_lib" value="libgazebo_ros_gpu_laser.so" />
      </xacro:if>
      <xacro:unless value="${gpu}">
        <xacro:property name="ray_type" value="ray" />
        <xacro:property name="plugin_lib" value="libgazebo_ros_laser.so" />
      </xacro:unless>
			<sensor type="${ray_type}" name="${prefix}_sensor">
				<pose>0 0 0 0 0 0</pose>
				<visualize>false</visualize>
				<update_rate>40</update_rate>
				<ray>
					<scan>
						<horizontal>
							<samples>1081</samples>
							<resolution>1</resolution>
							<min_angle>${min_angle}</min_angle>
							<max_angle>${max_angle}</max_angle>
						</horizontal>
					</scan>
					<range>
						<min>0.06</min>
						<max>20.0</max>
						<! resolution>0.004363323</resolution >
						<resolution>0.004359297</resolution>
						<! resolution>0.001</resolution >
					</range>
					<noise>
						<type>gaussian</type>
						<mean>0.0</mean>
						<stddev>0.01</stddev>
					</noise>
				</ray>
				<plugin name="${prefix}_controller" filename="${plugin_lib}">
					<topicName>${prefix_topic}/scan</topicName>
					<frameName>/${prefix}_link</frameName>
				</plugin>
			</sensor>
	</gazebo>
  </xacro:macro>
  -->
  <!-- Includes -->
  <!-- Includes -->
  <!-- links      		mesh_no
   base           		0
   shoulder       		1
   arm            		2
   forearm        		3
   wrist          		4
   arm_mico       		5
   arm_half1 (7dof)		6
   arm_half2 (7dof)		7
   wrist_spherical_1  8
   wrist_spherical_2  9

   hand 3 finger  		55
   hand_2finger   		56
   finger_proximal		57
   finger_distal      58
-->
  <!-- links      		mesh_no
   base           		0
   shoulder       		1
   arm            		2
   forearm        		3
   wrist          		4
   arm_mico       		5
   arm_half1 (7dof)		6
   arm_half2 (7dof)		7
   wrist_spherical_1  8
   wrist_spherical_2  9

   hand 3 finger  		55
   hand_2finger   		56
   finger_proximal		57
   finger_distal      58
-->
  <gazebo>
    <plugin filename="libgazebo_ros_control.so" name="ros_control">
      <robotParam>robot_description</robotParam>
      <controlPeriod>0.001</controlPeriod>
      <robotSimType>gazebo_ros_control/DefaultRobotHWSim</robotSimType>
      <legacyModeNS>true</legacyModeNS>
    </plugin>
  </gazebo>
  <!-- *************** -->
  <!-- Robots Elements -->
  <!-- *************** -->
  <!-- Here we create the robot elements using the xacro:macros imported at the beggining of this file -->
  <link name="robot_base_footprint">
    <visual>
      <origin rpy="0 0 0" xyz="0 0 0"/>
      <geometry>
        <box size="0.001 0.001 0.001"/>
      </geometry>
    </visual>
  </link>
  <joint name="robot_base_footprint_joint" type="fixed">
    <origin rpy="0 0 0" xyz="0 0 0.11"/>
    <!-- ${wheel_radius} property must be defined inside wheel description -->
    <parent link="robot_base_footprint"/>
    <child link="robot_base_link"/>
  </joint>
  <!-- BASE_LINK -->
  <link name="robot_base_link">
    <inertial>
      <mass value="25.0"/>
      <origin xyz="0 0 0"/>
      <inertia ixx="1.391" ixy="0.004" ixz="0.0" iyy="6.853" iyz="0.0" izz="6.125"/>
    </inertial>
    <visual>
      <origin rpy="0 0 0" xyz="0 0 0"/>
      <geometry>
        <mesh filename="package://summit_xl_description/meshes/bases/summit_xl_chassis.dae"/>
      </geometry>
      <material name="darkgrey">
        <color rgba="0.1 0.1 0.1 1"/>
      </material>
    </visual>
    <collision>
      <origin rpy="0 0 0 " xyz="0 0 0"/>
      <geometry>
        <mesh filename="package://summit_xl_description/meshes/bases/summit_xl_chassis_collision.dae"/>
      </geometry>
    </collision>
  </link>
  <!-- DOCKING CONTACTS -->
  <joint name="robot_base_docking_joint" type="fixed">
    <origin rpy="0 0 0 " xyz="0.284 0.012 0.068"/>
    <parent link="robot_base_link"/>
    <child link="robot_base_docking_contact_link"/>
  </joint>
  <!-- DOCKING LINK -->
  <link name="robot_base_docking_contact_link"/>
  <!--WHEEL TIRE -->
  <joint name="robot_front_right_wheel_joint" type="continuous">
    <parent link="robot_base_link"/>
    <child link="robot_front_right_wheel"/>
    <origin rpy="0 0 0" xyz="0.229 -0.235 0.0"/>
    <axis rpy="0 0 0" xyz="0 1 0"/>
    <limit effort="100" velocity="100"/>
    <joint_properties damping="0.0" friction="0.0"/>
  </joint>
  <link name="robot_front_right_wheel">
    <visual>
      <origin rpy="0 0 0" xyz="0 0 0"/>
      <geometry>
        <mesh filename="package://summit_xl_description/meshes/wheels/rubber_wheel_right.dae"/>
      </geometry>
    </visual>
    <collision>
      <origin rpy="1.5707963267948966 0 0" xyz="0 0 0"/>
      <geometry>
        <cylinder length="0.15" radius="0.11"/>
      </geometry>
    </collision>
    <inertial>
      <mass value="6.5"/>
      <origin xyz="0 0 0"/>
      <inertia ixx="0.031849999999999996" ixy="0" ixz="0" iyy="0.039325" iyz="0" izz="0.031849999999999996"/>
    </inertial>
  </link>
  <!-- Transmission is important to link the joints and the controller (see summit_xl_control/config/summit_xl_control.yaml)-->
  <transmission name="robot_front_right_wheel_joint_trans">
    <type>transmission_interface/SimpleTransmission</type>
    <joint name="robot_front_right_wheel_joint">
      <hardwareInterface>hardware_interface/VelocityJointInterface</hardwareInterface>
    </joint>
    <actuator name="robot_front_right_wheel_joint_motor">
      <mechanicalReduction>1</mechanicalReduction>
      <motorTorqueConstant>20</motorTorqueConstant>
    </actuator>
  </transmission>
  <gazebo reference="robot_front_right_wheel">
    <mu1 value="1.0"/>
    <mu2 value="1.0"/>
    <kp value="10000000.0"/>
    <kd value="1.0"/>
    <fdir1 value="1 0 0"/>
    <turnGravityOff>false</turnGravityOff>
  </gazebo>
  <!--WHEEL TIRE -->
  <joint name="robot_front_left_wheel_joint" type="continuous">
    <parent link="robot_base_link"/>
    <child link="robot_front_left_wheel"/>
    <origin rpy="0 0 0" xyz="0.229 0.235 0.0"/>
    <axis rpy="0 0 0" xyz="0 1 0"/>
    <limit effort="100" velocity="100"/>
    <joint_properties damping="0.0" friction="0.0"/>
  </joint>
  <link name="robot_front_left_wheel">
    <visual>
      <origin rpy="0 0 0" xyz="0 0 0"/>
      <geometry>
        <mesh filename="package://summit_xl_description/meshes/wheels/rubber_wheel_left.dae"/>
      </geometry>
    </visual>
    <collision>
      <origin rpy="1.5707963267948966 0 0" xyz="0 0 0"/>
      <geometry>
        <cylinder length="0.15" radius="0.11"/>
      </geometry>
    </collision>
    <inertial>
      <mass value="6.5"/>
      <origin xyz="0 0 0"/>
      <inertia ixx="0.031849999999999996" ixy="0" ixz="0" iyy="0.039325" iyz="0" izz="0.031849999999999996"/>
    </inertial>
  </link>
  <!-- Transmission is important to link the joints and the controller (see summit_xl_control/config/summit_xl_control.yaml)-->
  <transmission name="robot_front_left_wheel_joint_trans">
    <type>transmission_interface/SimpleTransmission</type>
    <joint name="robot_front_left_wheel_joint">
      <hardwareInterface>hardware_interface/VelocityJointInterface</hardwareInterface>
    </joint>
    <actuator name="robot_front_left_wheel_joint_motor">
      <mechanicalReduction>1</mechanicalReduction>
      <motorTorqueConstant>20</motorTorqueConstant>
    </actuator>
  </transmission>
  <gazebo reference="robot_front_left_wheel">
    <mu1 value="1.0"/>
    <mu2 value="1.0"/>
    <kp value="10000000.0"/>
    <kd value="1.0"/>
    <fdir1 value="1 0 0"/>
    <turnGravityOff>false</turnGravityOff>
  </gazebo>
  <!--WHEEL TIRE -->
  <joint name="robot_back_left_wheel_joint" type="continuous">
    <parent link="robot_base_link"/>
    <child link="robot_back_left_wheel"/>
    <origin rpy="0 0 0" xyz="-0.229 0.235 0.0"/>
    <axis rpy="0 0 0" xyz="0 1 0"/>
    <limit effort="100" velocity="100"/>
    <joint_properties damping="0.0" friction="0.0"/>
  </joint>
  <link name="robot_back_left_wheel">
    <visual>
      <origin rpy="0 0 0" xyz="0 0 0"/>
      <geometry>
        <mesh filename="package://summit_xl_description/meshes/wheels/rubber_wheel_left.dae"/>
      </geometry>
    </visual>
    <collision>
      <origin rpy="1.5707963267948966 0 0" xyz="0 0 0"/>
      <geometry>
        <cylinder length="0.15" radius="0.11"/>
      </geometry>
    </collision>
    <inertial>
      <mass value="6.5"/>
      <origin xyz="0 0 0"/>
      <inertia ixx="0.031849999999999996" ixy="0" ixz="0" iyy="0.039325" iyz="0" izz="0.031849999999999996"/>
    </inertial>
  </link>
  <!-- Transmission is important to link the joints and the controller (see summit_xl_control/config/summit_xl_control.yaml)-->
  <transmission name="robot_back_left_wheel_joint_trans">
    <type>transmission_interface/SimpleTransmission</type>
    <joint name="robot_back_left_wheel_joint">
      <hardwareInterface>hardware_interface/VelocityJointInterface</hardwareInterface>
    </joint>
    <actuator name="robot_back_left_wheel_joint_motor">
      <mechanicalReduction>1</mechanicalReduction>
      <motorTorqueConstant>20</motorTorqueConstant>
    </actuator>
  </transmission>
  <gazebo reference="robot_back_left_wheel">
    <mu1 value="1.0"/>
    <mu2 value="1.0"/>
    <kp value="10000000.0"/>
    <kd value="1.0"/>
    <fdir1 value="1 0 0"/>
    <turnGravityOff>false</turnGravityOff>
  </gazebo>
  <!--WHEEL TIRE -->
  <joint name="robot_back_right_wheel_joint" type="continuous">
    <parent link="robot_base_link"/>
    <child link="robot_back_right_wheel"/>
    <origin rpy="0 0 0" xyz="-0.229 -0.235 0.0"/>
    <axis rpy="0 0 0" xyz="0 1 0"/>
    <limit effort="100" velocity="100"/>
    <joint_properties damping="0.0" friction="0.0"/>
  </joint>
  <link name="robot_back_right_wheel">
    <visual>
      <origin rpy="0 0 0" xyz="0 0 0"/>
      <geometry>
        <mesh filename="package://summit_xl_description/meshes/wheels/rubber_wheel_right.dae"/>
      </geometry>
    </visual>
    <collision>
      <origin rpy="1.5707963267948966 0 0" xyz="0 0 0"/>
      <geometry>
        <cylinder length="0.15" radius="0.11"/>
      </geometry>
    </collision>
    <inertial>
      <mass value="6.5"/>
      <origin xyz="0 0 0"/>
      <inertia ixx="0.031849999999999996" ixy="0" ixz="0" iyy="0.039325" iyz="0" izz="0.031849999999999996"/>
    </inertial>
  </link>
  <!-- Transmission is important to link the joints and the controller (see summit_xl_control/config/summit_xl_control.yaml)-->
  <transmission name="robot_back_right_wheel_joint_trans">
    <type>transmission_interface/SimpleTransmission</type>
    <joint name="robot_back_right_wheel_joint">
      <hardwareInterface>hardware_interface/VelocityJointInterface</hardwareInterface>
    </joint>
    <actuator name="robot_back_right_wheel_joint_motor">
      <mechanicalReduction>1</mechanicalReduction>
      <motorTorqueConstant>20</motorTorqueConstant>
    </actuator>
  </transmission>
  <gazebo reference="robot_back_right_wheel">
    <mu1 value="1.0"/>
    <mu2 value="1.0"/>
    <kp value="10000000.0"/>
    <kd value="1.0"/>
    <fdir1 value="1 0 0"/>
    <turnGravityOff>false</turnGravityOff>
  </gazebo>
  <joint name="robot_imu_joint" type="fixed">
    <axis xyz="1 0 0"/>
    <!--origin xyz="0 0 0.2825"/-->
    <origin rpy="0 0 0" xyz="-0.18 0.0 0.170"/>
    <parent link="robot_base_link"/>
    <child link="robot_imu_link"/>
  </joint>
  <link name="robot_imu_link">
    <inertial>
      <origin rpy="0 0 0" xyz="0.0 0 0.01"/>
      <mass value="0.005"/>
      <inertia ixx="8.333333333333334e-10" ixy="0" ixz="0" iyy="8.333333333333334e-10" iyz="0" izz="8.333333333333334e-10"/>
    </inertial>
    <visual>
      <origin rpy="0 0 0" xyz="0 0 0"/>
      <geometry>
        <box size="0.001 0.001 0.001"/>
      </geometry>
    </visual>
    <!--collision>
	        <origin rpy="0 0 0" xyz="0 0 0"/>
	        <geometry>
	          <box size="0.001 0.001 0.001"/>
	        </geometry>
	      </collision-->
  </link>
  <!--<gazebo>-->
  <!--<plugin name="${prefix}_controller" filename="libgazebo_ros_imu.so">-->
  <!--<topicName>${ns}imu/data</topicName>-->
  <!--<serviceName>imu/service</serviceName>-->
  <!--<bodyName>${prefix}_link</bodyName>-->
  <!--<updateRateHZ>50.0</updateRateHZ>-->
  <!--<gaussianNoise>0.0</gaussianNoise>-->
  <!--</plugin>-->
  <!--</gazebo>-->
  <gazebo reference="robot_imu_link">
    <gravity>true</gravity>
    <sensor name="robot_imu_imu_sensor" type="imu">
      <always_on>true</always_on>
      <update_rate>100</update_rate>
      <visualize>true</visualize>
      <topic>__default_topic__</topic>
      <plugin filename="libgazebo_ros_imu_sensor.so" name="robot_imu_imu_plugin">
        <topicName>imu/data</topicName>
        <bodyName>robot_imu_link</bodyName>
        <updateRateHZ>100.0</updateRateHZ>
        <gaussianNoise>0.0</gaussianNoise>
        <xyzOffset>0 0 0</xyzOffset>
        <rpyOffset>0 0 0</rpyOffset>
        <frameName>robot_imu_link</frameName>
      </plugin>
      <pose>0 0 0 0 0 0</pose>
    </sensor>
  </gazebo>
  <!-- 2d laser -->
  <!--xacro:sensor_hokuyo_ust10lx prefix="$(arg prefix)front_laser" parent="$(arg prefix)base_link" prefix_topic="front_laser" gpu="$(arg gpu)">
            <origin xyz="0.0 0.0 0.33" rpy="0 0 0"/>
        </xacro:sensor_hokuyo_ust10lx-->
  <!-- 3d laser -->
  <!--xacro:sensor_rslidar_mems prefix="$(arg prefix)top_3d_laser" parent="$(arg prefix)base_link">
            <origin xyz="0.3134 0 0.2424" rpy="0 0 0"/>
        </xacro:sensor_rslidar_mems-->
  <!-- ptz camera -->
  <!--xacro:sensor_axis prefix="$(arg prefix)front_ptz_camera" parent="$(arg prefix)base_link">
            <origin xyz="0.19 0 0.26" rpy="0 ${15*PI/180} 0"/>
        </xacro:sensor_axis-->
  <!-- camera body, with origin at bottom screw mount -->
  <joint name="robot_front_rgbd_camera_joint" type="fixed">
    <origin rpy="0 0 0" xyz="0.324 0.012 0.172"/>
    <parent link="robot_base_link"/>
    <child link="robot_front_rgbd_camera_bottom_screw_frame"/>
  </joint>
  <link name="robot_front_rgbd_camera_bottom_screw_frame"/>
  <joint name="robot_front_rgbd_camera_link_joint" type="fixed">
    <origin rpy="0 0 0" xyz="0.011150000000000002 0.0475 0.0145"/>
    <parent link="robot_front_rgbd_camera_bottom_screw_frame"/>
    <child link="robot_front_rgbd_camera_link"/>
  </joint>
  <link name="robot_front_rgbd_camera_link">
    <visual>
      <!-- the mesh origin is at front plate in between the two infrared camera axes -->
      <!-- <origin xyz="${d455_zero_depth_to_glass-d455_cam_depth/2} ${-d455_cam_depth_py} 0" rpy="0 0 0"/> -->
      <origin rpy="1.5707963267948966 0 1.5707963267948966" xyz="0.0046500000000000005 -0.0475 0"/>
      <geometry>
        <!--box size="${d455_cam_depth} ${d455_cam_width} ${d455_cam_height}"/> 
	        <mesh filename="package://realsense2_description/meshes/d455.stl" scale="0.001 0.001 0.001" />-->
        <mesh filename="package://robotnik_sensors/meshes/intel_d435.dae"/>
      </geometry>
      <material name="aluminum"/>
    </visual>
    <collision>
      <origin rpy="0 0 0" xyz="-0.00845 -0.0475 0"/>
      <geometry>
        <box size="0.026 0.124 0.029"/>
      </geometry>
    </collision>
    <inertial>
      <!-- The following are not reliable values, and should not be used for modeling -->
      <mass value="0.072"/>
      <origin xyz="0 0 0"/>
      <inertia ixx="0.003881243" ixy="0.0" ixz="0.0" iyy="0.000498940" iyz="0.0" izz="0.003879257"/>
    </inertial>
  </link>
  <!-- camera depth joints and links -->
  <joint name="robot_front_rgbd_camera_depth_joint" type="fixed">
    <origin rpy="0 0 0" xyz="0 0 0"/>
    <parent link="robot_front_rgbd_camera_link"/>
    <child link="robot_front_rgbd_camera_depth_frame"/>
  </joint>
  <link name="robot_front_rgbd_camera_depth_frame"/>
  <joint name="robot_front_rgbd_camera_depth_optical_joint" type="fixed">
    <origin rpy="-1.5707963267948966 0 -1.5707963267948966" xyz="0 0 0"/>
    <parent link="robot_front_rgbd_camera_depth_frame"/>
    <child link="robot_front_rgbd_camera_depth_optical_frame"/>
  </joint>
  <link name="robot_front_rgbd_camera_depth_optical_frame"/>
  <!-- camera left IR joints and links -->
  <joint name="robot_front_rgbd_camera_infra1_joint" type="fixed">
    <origin rpy="0 0 0" xyz="0 0.0 0"/>
    <parent link="robot_front_rgbd_camera_link"/>
    <child link="robot_front_rgbd_camera_infra1_frame"/>
  </joint>
  <link name="robot_front_rgbd_camera_infra1_frame"/>
  <joint name="robot_front_rgbd_camera_infra1_optical_joint" type="fixed">
    <origin rpy="-1.5707963267948966 0 -1.5707963267948966" xyz="0 0 0"/>
    <parent link="robot_front_rgbd_camera_infra1_frame"/>
    <child link="robot_front_rgbd_camera_infra1_optical_frame"/>
  </joint>
  <link name="robot_front_rgbd_camera_infra1_optical_frame"/>
  <!-- camera right IR joints and links -->
  <joint name="robot_front_rgbd_camera_infra2_joint" type="fixed">
    <origin rpy="0 0 0" xyz="0 -0.095 0"/>
    <parent link="robot_front_rgbd_camera_link"/>
    <child link="robot_front_rgbd_camera_infra2_frame"/>
  </joint>
  <link name="robot_front_rgbd_camera_infra2_frame"/>
  <joint name="robot_front_rgbd_camera_infra2_optical_joint" type="fixed">
    <origin rpy="-1.5707963267948966 0 -1.5707963267948966" xyz="0 0 0"/>
    <parent link="robot_front_rgbd_camera_infra2_frame"/>
    <child link="robot_front_rgbd_camera_infra2_optical_frame"/>
  </joint>
  <link name="robot_front_rgbd_camera_infra2_optical_frame"/>
  <!-- camera color joints and links -->
  <joint name="robot_front_rgbd_camera_color_joint" type="fixed">
    <origin rpy="0 0 0" xyz="0 -0.059 0"/>
    <parent link="robot_front_rgbd_camera_link"/>
    <child link="robot_front_rgbd_camera_color_frame"/>
  </joint>
  <link name="robot_front_rgbd_camera_color_frame"/>
  <joint name="robot_front_rgbd_camera_color_optical_joint" type="fixed">
    <origin rpy="-1.5707963267948966 0 -1.5707963267948966" xyz="0 0 0"/>
    <parent link="robot_front_rgbd_camera_color_frame"/>
    <child link="robot_front_rgbd_camera_color_optical_frame"/>
  </joint>
  <link name="robot_front_rgbd_camera_color_optical_frame"/>
  <link name="robot_front_rgbd_camera_accel_frame"/>
  <link name="robot_front_rgbd_camera_accel_optical_frame"/>
  <link name="robot_front_rgbd_camera_gyro_frame"/>
  <link name="robot_front_rgbd_camera_gyro_optical_frame"/>
  <link name="robot_front_rgbd_camera_imu_optical_frame"/>
  <joint name="robot_front_rgbd_camera_accel_joint" type="fixed">
    <origin rpy="0 0 0" xyz="-0.01602 -0.03022 0.0074"/>
    <parent link="robot_front_rgbd_camera_link"/>
    <child link="robot_front_rgbd_camera_accel_frame"/>
  </joint>
  <joint name="robot_front_rgbd_camera_accel_optical_joint" type="fixed">
    <origin rpy="-1.5707963267948966 0 -1.5707963267948966" xyz="0 0 0"/>
    <parent link="robot_front_rgbd_camera_accel_frame"/>
    <child link="robot_front_rgbd_camera_accel_optical_frame"/>
  </joint>
  <joint name="robot_front_rgbd_camera_gyro_joint" type="fixed">
    <origin rpy="0 0 0" xyz="-0.01602 -0.03022 0.0074"/>
    <parent link="robot_front_rgbd_camera_link"/>
    <child link="robot_front_rgbd_camera_gyro_frame"/>
  </joint>
  <joint name="robot_front_rgbd_camera_gyro_optical_joint" type="fixed">
    <origin rpy="-1.5707963267948966 0 -1.5707963267948966" xyz="0 0 0"/>
    <parent link="robot_front_rgbd_camera_gyro_frame"/>
    <child link="robot_front_rgbd_camera_gyro_optical_frame"/>
  </joint>
  <joint name="robot_front_rgbd_camera_imu_optical_joint" type="fixed">
    <origin rpy="0 0 0" xyz="0 0 0"/>
    <parent link="robot_front_rgbd_camera_gyro_optical_frame"/>
    <child link="robot_front_rgbd_camera_imu_optical_frame"/>
  </joint>
  <joint name="robot_arm_rgbd_camera_base_joint" type="fixed">
    <origin rpy="0 0 0" xyz="0.324 0 0.172"/>
    <parent link="robot_j2n6s300_link_6"/>
    <child link="robot_arm_rgbd_camera_base_link"/>
  </joint>
  <link name="robot_arm_rgbd_camera_base_link"/>
  <!-- camera body, with origin at bottom screw mount -->
  <joint name="robot_arm_rgbd_camera_joint" type="fixed">
    <parent link="robot_arm_rgbd_camera_base_link"/>
    <child link="robot_arm_rgbd_camera_link"/>
    <origin rpy="0 0 0" xyz="0.01 0.02 0"/>
    <child link="robot_arm_rgbd_camera_link"/>
  </joint>
  <link name="robot_arm_rgbd_camera_link">
    <!-- camera link is aligned with the infrared sensor 1 that is "in the middle of the camera", not the one in the edge -->
    <visual>
      <origin rpy="1.5707963267948966 0 1.5707963267948966" xyz="0.0149 -0.0175 0"/>
      <geometry>
        <!-- <box size="${d435_cam_width} ${d435_cam_height} ${d435_cam_depth}"/> -->
        <mesh filename="package://robotnik_sensors/meshes/intel_d435.dae"/>
      </geometry>
    </visual>
    <collision>
      <origin rpy="0 0 0" xyz="0 -0.0175 0"/>
      <geometry>
        <box size="0.02505 0.09 0.025"/>
      </geometry>
    </collision>
    <inertial>
      <origin rpy="0 0 0" xyz="0.0025 -0.015 0.0"/>
      <mass value="0.1"/>
      <inertia ixx="7.270833333333333e-05" ixy="0" ixz="0" iyy="1.041666666666667e-05" iyz="0" izz="7.270833333333333e-05"/>
    </inertial>
  </link>
  <!-- camera depth joints and links -->
  <joint name="robot_arm_rgbd_camera_depth_joint" type="fixed">
    <origin rpy="0 0 0" xyz="0 0 0"/>
    <parent link="robot_arm_rgbd_camera_link"/>
    <child link="robot_arm_rgbd_camera_depth_frame"/>
  </joint>
  <link name="robot_arm_rgbd_camera_depth_frame"/>
  <joint name="robot_arm_rgbd_camera_depth_optical_joint" type="fixed">
    <origin rpy="-1.5707963267948966 0 -1.5707963267948966" xyz="0 0 0"/>
    <parent link="robot_arm_rgbd_camera_depth_frame"/>
    <child link="robot_arm_rgbd_camera_depth_optical_frame"/>
  </joint>
  <link name="robot_arm_rgbd_camera_depth_optical_frame"/>
  <!-- camera left IR joints and links -->
  <joint name="robot_arm_rgbd_camera_infra1_joint" type="fixed">
    <origin rpy="0 0 0" xyz="0 0.0 0"/>
    <parent link="robot_arm_rgbd_camera_link"/>
    <child link="robot_arm_rgbd_camera_infra1_frame"/>
  </joint>
  <link name="robot_arm_rgbd_camera_infra1_frame"/>
  <joint name="robot_arm_rgbd_camera_infra1_optical_joint" type="fixed">
    <origin rpy="-1.5707963267948966 0 -1.5707963267948966" xyz="0 0 0"/>
    <parent link="robot_arm_rgbd_camera_infra1_frame"/>
    <child link="robot_arm_rgbd_camera_infra1_optical_frame"/>
  </joint>
  <link name="robot_arm_rgbd_camera_infra1_optical_frame"/>
  <!-- camera right IR joints and links -->
  <joint name="robot_arm_rgbd_camera_infra2_joint" type="fixed">
    <origin rpy="0 0 0" xyz="0 -0.05 0"/>
    <parent link="robot_arm_rgbd_camera_link"/>
    <child link="robot_arm_rgbd_camera_infra2_frame"/>
  </joint>
  <link name="robot_arm_rgbd_camera_infra2_frame"/>
  <joint name="robot_arm_rgbd_camera_infra2_optical_joint" type="fixed">
    <origin rpy="-1.5707963267948966 0 -1.5707963267948966" xyz="0 0 0"/>
    <parent link="robot_arm_rgbd_camera_infra2_frame"/>
    <child link="robot_arm_rgbd_camera_infra2_optical_frame"/>
  </joint>
  <link name="robot_arm_rgbd_camera_infra2_optical_frame"/>
  <!-- camera color joints and links -->
  <joint name="robot_arm_rgbd_camera_color_joint" type="fixed">
    <origin rpy="0 0 0" xyz="0 0.015 0"/>
    <parent link="robot_arm_rgbd_camera_link"/>
    <child link="robot_arm_rgbd_camera_color_frame"/>
  </joint>
  <link name="robot_arm_rgbd_camera_color_frame"/>
  <joint name="robot_arm_rgbd_camera_color_optical_joint" type="fixed">
    <origin rpy="-1.5707963267948966 0 -1.5707963267948966" xyz="0 0 0"/>
    <parent link="robot_arm_rgbd_camera_color_frame"/>
    <child link="robot_arm_rgbd_camera_color_optical_frame"/>
  </joint>
  <link name="robot_arm_rgbd_camera_color_optical_frame"/>
  <gazebo reference="robot_arm_rgbd_camera_link">
    <self_collide>0</self_collide>
    <enable_wind>0</enable_wind>
    <kinematic>0</kinematic>
    <gravity>1</gravity>
    <!--<mu>1</mu>-->
    <mu2>1</mu2>
    <fdir1>0 0 0</fdir1>
    <!--<slip1>0</slip1>
     <slip2>0</slip2>-->
    <kp>1e+13</kp>
    <kd>1</kd>
    <!--<max_vel>0.01</max_vel>
     <min_depth>0</min_depth>-->
    <sensor name="robotcolor" type="camera">
      <camera name="robot">
        <horizontal_fov>1.2112585008840648</horizontal_fov>
        <image>
          <width>1920</width>
          <height>1080</height>
          <format>RGB_INT8</format>
        </image>
        <clip>
          <near>0.1</near>
          <far>100</far>
        </clip>
        <noise>
          <type>gaussian</type>
          <mean>0.0</mean>
          <stddev>0.007</stddev>
        </noise>
      </camera>
      <always_on>1</always_on>
      <update_rate>7</update_rate>
      <visualize>0</visualize>
      <plugin filename="libgazebo_ros_camera.so" name="robot_arm_rgbd_camerakortex_vision_controller">
        <alwaysOn>true</alwaysOn>
        <updateRate>7</updateRate>
        <cameraName>robot_color</cameraName>
        <imageTopicName>/robot/arm_rgbd_camera/rgb/image_raw</imageTopicName>
        <cameraInfoTopicName>/robot/arm_rgbd_camera/rgb/camera_info</cameraInfoTopicName>
        <frameName>/robot_arm_rgbd_camera_color_optical_frame</frameName>
        <!-- this is just which name the Image msg will have, it does not affect the simulation.
                However must be set to the optical_frame,  -->
        <hackBaseline>0.07</hackBaseline>
        <distortionK1>0.0</distortionK1>
        <distortionK2>0.0</distortionK2>
        <distortionK3>0.0</distortionK3>
        <distortionT1>0.0</distortionT1>
        <distortionT2>0.0</distortionT2>
        <ignoreTfPrefix>1</ignoreTfPrefix>
      </plugin>
    </sensor>
    <sensor name="robotired1" type="camera">
      <camera name="robot">
        <horizontal_fov>1.4870205226991688</horizontal_fov>
        <image>
          <width>1280</width>
          <height>720</height>
          <format>L_INT8</format>
        </image>
        <clip>
          <near>0.1</near>
          <far>100</far>
        </clip>
        <noise>
          <type>gaussian</type>
          <mean>0.0</mean>
          <stddev>0.05</stddev>
        </noise>
      </camera>
      <always_on>1</always_on>
      <update_rate>7</update_rate>
      <visualize>0</visualize>
    </sensor>
    <sensor name="robotired2" type="camera">
      <camera name="robot">
        <horizontal_fov>1.4870205226991688</horizontal_fov>
        <image>
          <width>1280</width>
          <height>720</height>
          <format>L_INT8</format>
        </image>
        <clip>
          <near>0.1</near>
          <far>100</far>
        </clip>
        <noise>
          <type>gaussian</type>
          <mean>0.0</mean>
          <stddev>0.05</stddev>
        </noise>
      </camera>
      <always_on>1</always_on>
      <update_rate>7</update_rate>
      <visualize>0</visualize>
    </sensor>
    <sensor name="robotdepth" type="depth">
      <camera name="robot">
        <horizontal_fov>1.4870205226991688</horizontal_fov>
        <image>
          <width>1280</width>
          <height>720</height>
        </image>
        <clip>
          <near>0.1</near>
          <far>100</far>
        </clip>
        <noise>
          <type>gaussian</type>
          <mean>0.0</mean>
          <stddev>0.100</stddev>
        </noise>
      </camera>
      <always_on/>
      <update_rate>7</update_rate>
      <visualize>0</visualize>
    </sensor>
  </gazebo>
  <gazebo>
    <plugin filename="librealsense_gazebo_plugin.so" name="robot_controller">
      <prefix>robot</prefix>
      <depthUpdateRate>7</depthUpdateRate>
      <colorUpdateRate>7</colorUpdateRate>
      <infraredUpdateRate>7</infraredUpdateRate>
      <depthTopicName>/robot/arm_rgbd_camera/depth/image_raw</depthTopicName>
      <depthCameraInfoTopicName>/robot/arm_rgbd_camera/depth/camera_info</depthCameraInfoTopicName>
      <colorTopicName>/robot/arm_rgbd_camera/color/image_raw</colorTopicName>
      <colorCameraInfoTopicName>/robot/arm_rgbd_camera/color/camera_info</colorCameraInfoTopicName>
      <infrared1TopicName>/robot/arm_rgbd_camera/infra1/image_raw</infrared1TopicName>
      <infrared1CameraInfoTopicName>/robot/arm_rgbd_camera/infra1/camera_info</infrared1CameraInfoTopicName>
      <infrared2TopicName>/robot/arm_rgbd_camera/infra2/image_raw</infrared2TopicName>
      <infrared2CameraInfoTopicName>/robot/arm_rgbd_camera/infra2/camera_info</infrared2CameraInfoTopicName>
      <colorOpticalframeName>robot_arm_rgbd_camera_color_optical_frame</colorOpticalframeName>
      <depthOpticalframeName>robot_arm_rgbd_camera_depth_optical_frame</depthOpticalframeName>
      <infrared1OpticalframeName>robot_arm_rgbd_camera_left_ir_optical_frame</infrared1OpticalframeName>
      <infrared2OpticalframeName>robot_arm_rgbd_camera_right_ir_optical_frame</infrared2OpticalframeName>
      <rangeMinDepth>0.105</rangeMinDepth>
      <rangeMaxDepth>10.0</rangeMaxDepth>
      <pointCloud>true</pointCloud>
      <pointCloudTopicName>/robot/arm_rgbd_camera/depth/points</pointCloudTopicName>
      <pointCloudCutoff>0.105</pointCloudCutoff>
    </plugin>
  </gazebo>
  <!-- GPS -->
  <!--xacro:sensor_gps prefix="$(arg prefix)gps" parent="$(arg prefix)base_link">
            <origin xyz="-0.28 0 0.6676" rpy="0 0 0"/>
        </xacro:sensor_gps-->
  <!-- Instance jaco arm -->
  <joint name="robot_arm_base_joint" type="fixed">
    <origin rpy="0.0 0.0 0.0" xyz="0.204 0.0 0.11"/>
    <parent link="robot_base_link"/>
    <child link="robot_arm_base_link"/>
    <axis xyz="0 0 0"/>
  </joint>
  <link name="robot_arm_base_link"/>
  <!-- ros_control plugin -->
  <gazebo>
    <plugin filename="libgazebo_ros_control.so" name="gazebo_ros_control">
      <robotNamespace>robot_j2n6s300</robotNamespace>
      <robotSimType>gazebo_ros_control/DefaultRobotHWSim</robotSimType>
      <legacyModeNS>true</legacyModeNS>
    </plugin>
  </gazebo>
  <link name="robot_j2n6s300_link_base">
    <visual>
      <geometry>
        <mesh filename="package://kinova_description/meshes/base.dae"/>
      </geometry>
      <material name="carbon_fiber">
        <color rgba="0.792156862745098 0.819607843137255 0.933333333333333 1"/>
      </material>
    </visual>
    <collision>
      <geometry>
        <mesh filename="package://kinova_description/meshes/base.dae"/>
      </geometry>
    </collision>
    <inertial>
      <mass value="0.46784"/>
      <origin rpy="0 0 0" xyz="0 0 0.1255"/>
      <inertia ixx="0.000951270861568" ixy="0" ixz="0" iyy="0.000951270861568" iyz="0" izz="0.00037427200000000004"/>
    </inertial>
  </link>
  <joint name="robot_j2n6s300_joint_base" type="fixed">
    <parent link="robot_arm_base_link"/>
    <child link="robot_j2n6s300_link_base"/>
    <axis xyz="0 0 0"/>
    <limit effort="0" lower="0" upper="0" velocity="0"/>
    <origin rpy="0 0 0" xyz="0 0 0"/>
    <dynamics damping="0.0" friction="0.0"/>
  </joint>
  <link name="robot_j2n6s300_link_1">
    <visual>
      <geometry>
        <mesh filename="package://kinova_description/meshes/shoulder.dae"/>
      </geometry>
      <material name="carbon_fiber">
        <color rgba="0.792156862745098 0.819607843137255 0.933333333333333 1"/>
      </material>
    </visual>
    <visual>
      <geometry>
        <mesh filename="package://kinova_description/meshes/ring_big.dae"/>
      </geometry>
    </visual>
    <collision>
      <geometry>
        <mesh filename="package://kinova_description/meshes/shoulder.dae"/>
      </geometry>
    </collision>
    <inertial>
      <mass value="0.7477"/>
      <origin xyz="0 -0.002 -0.0605"/>
      <inertia ixx="0.0015203172520400004" ixy="0" ixz="0" iyy="0.0015203172520400004" iyz="0" izz="0.00059816"/>
    </inertial>
  </link>
  <joint name="robot_j2n6s300_joint_1" type="continuous">
    <parent link="robot_j2n6s300_link_base"/>
    <child link="robot_j2n6s300_link_1"/>
    <axis xyz="0 0 1"/>
    <limit effort="40" lower="-6.283185307179586" upper="6.283185307179586" velocity="0.6283185307179586"/>
    <origin rpy="0 3.141592653589793 0" xyz="0 0 0.15675"/>
    <dynamics damping="0.0" friction="0.0"/>
  </joint>
  <transmission name="robot_j2n6s300_joint_1_trans">
    <type>transmission_interface/SimpleTransmission</type>
    <joint name="robot_j2n6s300_joint_1">
      <hardwareInterface>hardware_interface/EffortJointInterface</hardwareInterface>
    </joint>
    <actuator name="robot_j2n6s300_joint_1_actuator">
      <hardwareInterface>hardware_interface/EffortJointInterface</hardwareInterface>
      <mechanicalReduction>160</mechanicalReduction>
    </actuator>
  </transmission>
  <!--For torque sensing in simulation-->
  <gazebo reference="robot_j2n6s300_joint_1">
    <provideFeedback>true</provideFeedback>
  </gazebo>
  <gazebo>
    <plugin filename="libgazebo_ros_ft_sensor.so" name="ft_sensor">
      <updateRate>30.0</updateRate>
      <topicName>robot_j2n6s300_joint_1_ft_sensor_topic</topicName>
      <jointName>robot_j2n6s300_joint_1</jointName>
    </plugin>
  </gazebo>
  <link name="robot_j2n6s300_link_2">
    <visual>
      <geometry>
        <mesh filename="package://kinova_description/meshes/arm.dae"/>
      </geometry>
      <material name="carbon_fiber">
        <color rgba="0.792156862745098 0.819607843137255 0.933333333333333 1"/>
      </material>
    </visual>
    <visual>
      <geometry>
        <mesh filename="package://kinova_description/meshes/ring_big.dae"/>
      </geometry>
    </visual>
    <collision>
      <geometry>
        <mesh filename="package://kinova_description/meshes/arm.dae"/>
      </geometry>
    </collision>
    <inertial>
      <mass value="0.99"/>
      <origin xyz="0 -0.2065 -0.01"/>
      <inertia ixx="0.010502207990999999" ixy="0" ixz="0" iyy="0.0007920000000000001" iyz="0" izz="0.010502207990999999"/>
    </inertial>
  </link>
  <joint name="robot_j2n6s300_joint_2" type="revolute">
    <parent link="robot_j2n6s300_link_1"/>
    <child link="robot_j2n6s300_link_2"/>
    <axis xyz="0 0 1"/>
    <limit effort="80" lower="0.8203047484373349" upper="5.462880558742252" velocity="0.6283185307179586"/>
    <origin rpy="-1.5707963267948966 0 3.141592653589793" xyz="0 0.0016 -0.11875"/>
    <dynamics damping="0.0" friction="0.0"/>
  </joint>
  <transmission name="robot_j2n6s300_joint_2_trans">
    <type>transmission_interface/SimpleTransmission</type>
    <joint name="robot_j2n6s300_joint_2">
      <hardwareInterface>hardware_interface/EffortJointInterface</hardwareInterface>
    </joint>
    <actuator name="robot_j2n6s300_joint_2_actuator">
      <hardwareInterface>hardware_interface/EffortJointInterface</hardwareInterface>
      <mechanicalReduction>160</mechanicalReduction>
    </actuator>
  </transmission>
  <!--For torque sensing in simulation-->
  <gazebo reference="robot_j2n6s300_joint_2">
    <provideFeedback>true</provideFeedback>
  </gazebo>
  <gazebo>
    <plugin filename="libgazebo_ros_ft_sensor.so" name="ft_sensor">
      <updateRate>30.0</updateRate>
      <topicName>robot_j2n6s300_joint_2_ft_sensor_topic</topicName>
      <jointName>robot_j2n6s300_joint_2</jointName>
    </plugin>
  </gazebo>
  <link name="robot_j2n6s300_link_3">
    <visual>
      <geometry>
        <mesh filename="package://kinova_description/meshes/forearm.dae"/>
      </geometry>
      <material name="carbon_fiber">
        <color rgba="0.792156862745098 0.819607843137255 0.933333333333333 1"/>
      </material>
    </visual>
    <visual>
      <geometry>
        <mesh filename="package://kinova_description/meshes/ring_big.dae"/>
      </geometry>
    </visual>
    <collision>
      <geometry>
        <mesh filename="package://kinova_description/meshes/forearm.dae"/>
      </geometry>
    </collision>
    <inertial>
      <mass value="0.6763"/>
      <origin xyz="0 0.081 -0.0086"/>
      <inertia ixx="0.0014202243190800001" ixy="0" ixz="0" iyy="0.000304335" iyz="0" izz="0.0014202243190800001"/>
    </inertial>
  </link>
  <joint name="robot_j2n6s300_joint_3" type="revolute">
    <parent link="robot_j2n6s300_link_2"/>
    <child link="robot_j2n6s300_link_3"/>
    <axis xyz="0 0 1"/>
    <limit effort="40" lower="0.33161255787892263" upper="5.951572749300664" velocity="0.6283185307179586"/>
    <origin rpy="0 3.141592653589793 0" xyz="0 -0.410 0"/>
    <dynamics damping="0.0" friction="0.0"/>
  </joint>
  <transmission name="robot_j2n6s300_joint_3_trans">
    <type>transmission_interface/SimpleTransmission</type>
    <joint name="robot_j2n6s300_joint_3">
      <hardwareInterface>hardware_interface/EffortJointInterface</hardwareInterface>
    </joint>
    <actuator name="robot_j2n6s300_joint_3_actuator">
      <hardwareInterface>hardware_interface/EffortJointInterface</hardwareInterface>
      <mechanicalReduction>160</mechanicalReduction>
    </actuator>
  </transmission>
  <!--For torque sensing in simulation-->
  <gazebo reference="robot_j2n6s300_joint_3">
    <provideFeedback>true</provideFeedback>
  </gazebo>
  <gazebo>
    <plugin filename="libgazebo_ros_ft_sensor.so" name="ft_sensor">
      <updateRate>30.0</updateRate>
      <topicName>robot_j2n6s300_joint_3_ft_sensor_topic</topicName>
      <jointName>robot_j2n6s300_joint_3</jointName>
    </plugin>
  </gazebo>
  <link name="robot_j2n6s300_link_4">
    <visual>
      <geometry>
        <mesh filename="package://kinova_description/meshes/wrist.dae"/>
      </geometry>
      <material name="carbon_fiber">
        <color rgba="0.792156862745098 0.819607843137255 0.933333333333333 1"/>
      </material>
    </visual>
    <visual>
      <geometry>
        <mesh filename="package://kinova_description/meshes/ring_small.dae"/>
      </geometry>
    </visual>
    <collision>
      <geometry>
        <mesh filename="package://kinova_description/meshes/wrist.dae"/>
      </geometry>
    </collision>
    <inertial>
      <mass value="0.426367"/>
      <origin xyz="0 -0.037 -0.0642"/>
      <inertia ixx="7.734969059999999e-05" ixy="0" ixz="0" iyy="7.734969059999999e-05" iyz="0" izz="0.0001428"/>
    </inertial>
  </link>
  <joint name="robot_j2n6s300_joint_4" type="continuous">
    <parent link="robot_j2n6s300_link_3"/>
    <child link="robot_j2n6s300_link_4"/>
    <axis xyz="0 0 1"/>
    <limit effort="20" lower="-6.283185307179586" upper="6.283185307179586" velocity="0.8377580409572781"/>
    <origin rpy="-1.5707963267948966 0 3.141592653589793" xyz="0 0.2073 -0.0114"/>
    <dynamics damping="0.0" friction="0.0"/>
  </joint>
  <transmission name="robot_j2n6s300_joint_4_trans">
    <type>transmission_interface/SimpleTransmission</type>
    <joint name="robot_j2n6s300_joint_4">
      <hardwareInterface>hardware_interface/EffortJointInterface</hardwareInterface>
    </joint>
    <actuator name="robot_j2n6s300_joint_4_actuator">
      <hardwareInterface>hardware_interface/EffortJointInterface</hardwareInterface>
      <mechanicalReduction>160</mechanicalReduction>
    </actuator>
  </transmission>
  <!--For torque sensing in simulation-->
  <gazebo reference="robot_j2n6s300_joint_4">
    <provideFeedback>true</provideFeedback>
  </gazebo>
  <gazebo>
    <plugin filename="libgazebo_ros_ft_sensor.so" name="ft_sensor">
      <updateRate>30.0</updateRate>
      <topicName>robot_j2n6s300_joint_4_ft_sensor_topic</topicName>
      <jointName>robot_j2n6s300_joint_4</jointName>
    </plugin>
  </gazebo>
  <link name="robot_j2n6s300_link_5">
    <visual>
      <geometry>
        <mesh filename="package://kinova_description/meshes/wrist.dae"/>
      </geometry>
      <material name="carbon_fiber">
        <color rgba="0.792156862745098 0.819607843137255 0.933333333333333 1"/>
      </material>
    </visual>
    <visual>
      <geometry>
        <mesh filename="package://kinova_description/meshes/ring_small.dae"/>
      </geometry>
    </visual>
    <collision>
      <geometry>
        <mesh filename="package://kinova_description/meshes/wrist.dae"/>
      </geometry>
    </collision>
    <inertial>
      <mass value="0.426367"/>
      <origin xyz="0 -0.037 -0.0642"/>
      <inertia ixx="7.734969059999999e-05" ixy="0" ixz="0" iyy="7.734969059999999e-05" iyz="0" izz="0.0001428"/>
    </inertial>
  </link>
  <joint name="robot_j2n6s300_joint_5" type="continuous">
    <parent link="robot_j2n6s300_link_4"/>
    <child link="robot_j2n6s300_link_5"/>
    <axis xyz="0 0 1"/>
    <limit effort="20" lower="-6.283185307179586" upper="6.283185307179586" velocity="0.8377580409572781"/>
    <origin rpy="1.0471975511965976 0 3.141592653589793" xyz="0 -0.03703 -0.06414"/>
    <dynamics damping="0.0" friction="0.0"/>
  </joint>
  <transmission name="robot_j2n6s300_joint_5_trans">
    <type>transmission_interface/SimpleTransmission</type>
    <joint name="robot_j2n6s300_joint_5">
      <hardwareInterface>hardware_interface/EffortJointInterface</hardwareInterface>
    </joint>
    <actuator name="robot_j2n6s300_joint_5_actuator">
      <hardwareInterface>hardware_interface/EffortJointInterface</hardwareInterface>
      <mechanicalReduction>160</mechanicalReduction>
    </actuator>
  </transmission>
  <!--For torque sensing in simulation-->
  <gazebo reference="robot_j2n6s300_joint_5">
    <provideFeedback>true</provideFeedback>
  </gazebo>
  <gazebo>
    <plugin filename="libgazebo_ros_ft_sensor.so" name="ft_sensor">
      <updateRate>30.0</updateRate>
      <topicName>robot_j2n6s300_joint_5_ft_sensor_topic</topicName>
      <jointName>robot_j2n6s300_joint_5</jointName>
    </plugin>
  </gazebo>
  <link name="robot_j2n6s300_link_6">
    <visual>
      <geometry>
        <mesh filename="package://kinova_description/meshes/hand_3finger.dae"/>
      </geometry>
      <material name="carbon_fiber">
        <color rgba="0.792156862745098 0.819607843137255 0.933333333333333 1"/>
      </material>
    </visual>
    <visual>
      <geometry>
        <mesh filename="package://kinova_description/meshes/ring_small.dae"/>
      </geometry>
    </visual>
    <collision>
      <geometry>
        <mesh filename="package://kinova_description/meshes/hand_3finger.dae"/>
      </geometry>
    </collision>
    <inertial>
      <mass value="0.99"/>
      <origin xyz="0 0 -0.06"/>
      <inertia ixx="0.00034532361869999995" ixy="0" ixz="0" iyy="0.00034532361869999995" iyz="0" izz="0.0005815999999999999"/>
    </inertial>
  </link>
  <joint name="robot_j2n6s300_joint_6" type="continuous">
    <parent link="robot_j2n6s300_link_5"/>
    <child link="robot_j2n6s300_link_6"/>
    <axis xyz="0 0 1"/>
    <limit effort="20" lower="-6.283185307179586" upper="6.283185307179586" velocity="0.8377580409572781"/>
    <origin rpy="1.0471975511965976 0 3.141592653589793" xyz="0 -0.03703 -0.06414"/>
    <dynamics damping="0.0" friction="0.0"/>
  </joint>
  <transmission name="robot_j2n6s300_joint_6_trans">
    <type>transmission_interface/SimpleTransmission</type>
    <joint name="robot_j2n6s300_joint_6">
      <hardwareInterface>hardware_interface/EffortJointInterface</hardwareInterface>
    </joint>
    <actuator name="robot_j2n6s300_joint_6_actuator">
      <hardwareInterface>hardware_interface/EffortJointInterface</hardwareInterface>
      <mechanicalReduction>160</mechanicalReduction>
    </actuator>
  </transmission>
  <!--For torque sensing in simulation-->
  <gazebo reference="robot_j2n6s300_joint_6">
    <provideFeedback>true</provideFeedback>
  </gazebo>
  <gazebo>
    <plugin filename="libgazebo_ros_ft_sensor.so" name="ft_sensor">
      <updateRate>30.0</updateRate>
      <topicName>robot_j2n6s300_joint_6_ft_sensor_topic</topicName>
      <jointName>robot_j2n6s300_joint_6</jointName>
    </plugin>
  </gazebo>
  <link name="robot_j2n6s300_end_effector"/>
  <joint name="robot_j2n6s300_joint_end_effector" type="fixed">
    <parent link="robot_j2n6s300_link_6"/>
    <child link="robot_j2n6s300_end_effector"/>
    <axis xyz="0 0 0"/>
    <limit effort="2000" lower="0" upper="0" velocity="1"/>
    <origin rpy="3.141592653589793 0 1.5707963267948966" xyz="0 0 -0.1600"/>
  </joint>
  <link name="robot_j2n6s300_link_finger_1">
    <visual>
      <geometry>
        <mesh filename="package://kinova_description/meshes/finger_proximal.dae"/>
      </geometry>
      <material name="carbon_fiber">
        <color rgba="0.792156862745098 0.819607843137255 0.933333333333333 1"/>
      </material>
    </visual>
    <collision>
      <geometry>
        <mesh filename="package://kinova_description/meshes/finger_proximal.dae"/>
      </geometry>
    </collision>
    <inertial>
      <mass value="0.01"/>
      <origin xyz="0.022 0 0"/>
      <inertia ixx="7.8999684e-07" ixy="0" ixz="0" iyy="7.8999684e-07" iyz="0" izz="8e-08"/>
    </inertial>
  </link>
  <joint name="robot_j2n6s300_joint_finger_1" type="revolute">
    <parent link="robot_j2n6s300_link_6"/>
    <child link="robot_j2n6s300_link_finger_1"/>
    <axis xyz="0 0 1"/>
    <origin rpy="-1.570796327 .649262481663582 1.35961148639407" xyz="0.00279 0.03126 -0.11467"/>
    <limit effort="2" lower="0" upper="1.51" velocity="1"/>
  </joint>
  <transmission name="robot_j2n6s300_joint_finger_1_trans">
    <type>transmission_interface/SimpleTransmission</type>
    <joint name="robot_j2n6s300_joint_finger_1">
      <hardwareInterface>hardware_interface/EffortJointInterface</hardwareInterface>
    </joint>
    <actuator name="robot_j2n6s300_joint_finger_1_actuator">
      <hardwareInterface>hardware_interface/EffortJointInterface</hardwareInterface>
      <mechanicalReduction>1</mechanicalReduction>
    </actuator>
  </transmission>
  <link name="robot_j2n6s300_link_finger_tip_1">
    <visual>
      <geometry>
        <mesh filename="package://kinova_description/meshes/finger_distal.dae"/>
      </geometry>
      <material name="carbon_fiber">
        <color rgba="0.792156862745098 0.819607843137255 0.933333333333333 1"/>
      </material>
    </visual>
    <collision>
      <geometry>
        <mesh filename="package://kinova_description/meshes/finger_distal.dae"/>
      </geometry>
    </collision>
    <inertial>
      <mass value="0.01"/>
      <origin xyz="0.022 0 0"/>
      <inertia ixx="7.8999684e-07" ixy="0" ixz="0" iyy="7.8999684e-07" iyz="0" izz="8e-08"/>
    </inertial>
  </link>
  <joint name="robot_j2n6s300_joint_finger_tip_1" type="revolute">
    <parent link="robot_j2n6s300_link_finger_1"/>
    <child link="robot_j2n6s300_link_finger_tip_1"/>
    <axis xyz="0 0 1"/>
    <origin rpy="0 0 0" xyz="0.044 -0.003 0"/>
    <limit effort="2" lower="0" upper="2" velocity="1"/>
  </joint>
  <transmission name="robot_j2n6s300_joint_finger_tip_1_trans">
    <type>transmission_interface/SimpleTransmission</type>
    <joint name="robot_j2n6s300_joint_finger_tip_1">
      <hardwareInterface>hardware_interface/EffortJointInterface</hardwareInterface>
    </joint>
    <actuator name="robot_j2n6s300_joint_finger_tip_1_actuator">
      <hardwareInterface>hardware_interface/EffortJointInterface</hardwareInterface>
      <mechanicalReduction>1</mechanicalReduction>
    </actuator>
  </transmission>
  <link name="robot_j2n6s300_link_finger_2">
    <visual>
      <geometry>
        <mesh filename="package://kinova_description/meshes/finger_proximal.dae"/>
      </geometry>
      <material name="carbon_fiber">
        <color rgba="0.792156862745098 0.819607843137255 0.933333333333333 1"/>
      </material>
    </visual>
    <collision>
      <geometry>
        <mesh filename="package://kinova_description/meshes/finger_proximal.dae"/>
      </geometry>
    </collision>
    <inertial>
      <mass value="0.01"/>
      <origin xyz="0.022 0 0"/>
      <inertia ixx="7.8999684e-07" ixy="0" ixz="0" iyy="7.8999684e-07" iyz="0" izz="8e-08"/>
    </inertial>
  </link>
  <joint name="robot_j2n6s300_joint_finger_2" type="revolute">
    <parent link="robot_j2n6s300_link_6"/>
    <child link="robot_j2n6s300_link_finger_2"/>
    <axis xyz="0 0 1"/>
    <origin rpy="-1.570796327 .649262481663582 -1.38614049188413" xyz="0.02226 -0.02707 -0.11482"/>
    <limit effort="2" lower="0" upper="1.51" velocity="1"/>
  </joint>
  <transmission name="robot_j2n6s300_joint_finger_2_trans">
    <type>transmission_interface/SimpleTransmission</type>
    <joint name="robot_j2n6s300_joint_finger_2">
      <hardwareInterface>hardware_interface/EffortJointInterface</hardwareInterface>
    </joint>
    <actuator name="robot_j2n6s300_joint_finger_2_actuator">
      <hardwareInterface>hardware_interface/EffortJointInterface</hardwareInterface>
      <mechanicalReduction>1</mechanicalReduction>
    </actuator>
  </transmission>
  <link name="robot_j2n6s300_link_finger_tip_2">
    <visual>
      <geometry>
        <mesh filename="package://kinova_description/meshes/finger_distal.dae"/>
      </geometry>
      <material name="carbon_fiber">
        <color rgba="0.792156862745098 0.819607843137255 0.933333333333333 1"/>
      </material>
    </visual>
    <collision>
      <geometry>
        <mesh filename="package://kinova_description/meshes/finger_distal.dae"/>
      </geometry>
    </collision>
    <inertial>
      <mass value="0.01"/>
      <origin xyz="0.022 0 0"/>
      <inertia ixx="7.8999684e-07" ixy="0" ixz="0" iyy="7.8999684e-07" iyz="0" izz="8e-08"/>
    </inertial>
  </link>
  <joint name="robot_j2n6s300_joint_finger_tip_2" type="revolute">
    <parent link="robot_j2n6s300_link_finger_2"/>
    <child link="robot_j2n6s300_link_finger_tip_2"/>
    <axis xyz="0 0 1"/>
    <origin rpy="0 0 0" xyz="0.044 -0.003 0"/>
    <limit effort="2" lower="0" upper="2" velocity="1"/>
  </joint>
  <transmission name="robot_j2n6s300_joint_finger_tip_2_trans">
    <type>transmission_interface/SimpleTransmission</type>
    <joint name="robot_j2n6s300_joint_finger_tip_2">
      <hardwareInterface>hardware_interface/EffortJointInterface</hardwareInterface>
    </joint>
    <actuator name="robot_j2n6s300_joint_finger_tip_2_actuator">
      <hardwareInterface>hardware_interface/EffortJointInterface</hardwareInterface>
      <mechanicalReduction>1</mechanicalReduction>
    </actuator>
  </transmission>
  <link name="robot_j2n6s300_link_finger_3">
    <visual>
      <geometry>
        <mesh filename="package://kinova_description/meshes/finger_proximal.dae"/>
      </geometry>
      <material name="carbon_fiber">
        <color rgba="0.792156862745098 0.819607843137255 0.933333333333333 1"/>
      </material>
    </visual>
    <collision>
      <geometry>
        <mesh filename="package://kinova_description/meshes/finger_proximal.dae"/>
      </geometry>
    </collision>
    <inertial>
      <mass value="0.01"/>
      <origin xyz="0.022 0 0"/>
      <inertia ixx="7.8999684e-07" ixy="0" ixz="0" iyy="7.8999684e-07" iyz="0" izz="8e-08"/>
    </inertial>
  </link>
  <joint name="robot_j2n6s300_joint_finger_3" type="revolute">
    <parent link="robot_j2n6s300_link_6"/>
    <child link="robot_j2n6s300_link_finger_3"/>
    <axis xyz="0 0 1"/>
    <origin rpy="-1.570796327 .649262481663582 -1.75545216211587" xyz="-0.02226 -0.02707 -0.11482"/>
    <limit effort="2" lower="0" upper="1.51" velocity="1"/>
  </joint>
  <transmission name="robot_j2n6s300_joint_finger_3_trans">
    <type>transmission_interface/SimpleTransmission</type>
    <joint name="robot_j2n6s300_joint_finger_3">
      <hardwareInterface>hardware_interface/EffortJointInterface</hardwareInterface>
    </joint>
    <actuator name="robot_j2n6s300_joint_finger_3_actuator">
      <hardwareInterface>hardware_interface/EffortJointInterface</hardwareInterface>
      <mechanicalReduction>1</mechanicalReduction>
    </actuator>
  </transmission>
  <link name="robot_j2n6s300_link_finger_tip_3">
    <visual>
      <geometry>
        <mesh filename="package://kinova_description/meshes/finger_distal.dae"/>
      </geometry>
      <material name="carbon_fiber">
        <color rgba="0.792156862745098 0.819607843137255 0.933333333333333 1"/>
      </material>
    </visual>
    <collision>
      <geometry>
        <mesh filename="package://kinova_description/meshes/finger_distal.dae"/>
      </geometry>
    </collision>
    <inertial>
      <mass value="0.01"/>
      <origin xyz="0.022 0 0"/>
      <inertia ixx="7.8999684e-07" ixy="0" ixz="0" iyy="7.8999684e-07" iyz="0" izz="8e-08"/>
    </inertial>
  </link>
  <joint name="robot_j2n6s300_joint_finger_tip_3" type="revolute">
    <parent link="robot_j2n6s300_link_finger_3"/>
    <child link="robot_j2n6s300_link_finger_tip_3"/>
    <axis xyz="0 0 1"/>
    <origin rpy="0 0 0" xyz="0.044 -0.003 0"/>
    <limit effort="2" lower="0" upper="2" velocity="1"/>
  </joint>
  <transmission name="robot_j2n6s300_joint_finger_tip_3_trans">
    <type>transmission_interface/SimpleTransmission</type>
    <joint name="robot_j2n6s300_joint_finger_tip_3">
      <hardwareInterface>hardware_interface/EffortJointInterface</hardwareInterface>
    </joint>
    <actuator name="robot_j2n6s300_joint_finger_tip_3_actuator">
      <hardwareInterface>hardware_interface/EffortJointInterface</hardwareInterface>
      <mechanicalReduction>1</mechanicalReduction>
    </actuator>
  </transmission>
</robot>
