<sdf version='1.7'>
  <world name='default'>
    <plugin name="model_attachment" filename="libboeing_gazebo_model_attachment_plugin_lib.so"/>
    <light name='sun' type='directional'>
      <cast_shadows>1</cast_shadows>
      <pose>0 0 10 0 -0 0</pose>
      <diffuse>0.8 0.8 0.8 1</diffuse>
      <specular>0.2 0.2 0.2 1</specular>
      <attenuation>
        <range>1000</range>
        <constant>0.9</constant>
        <linear>0.01</linear>
        <quadratic>0.001</quadratic>
      </attenuation>
      <direction>-0.5 0.1 -0.9</direction>
      <spot>
        <inner_angle>0</inner_angle>
        <outer_angle>0</outer_angle>
        <falloff>0</falloff>
      </spot>
    </light>
    <model name='ground_plane'>
      <static>1</static>
      <link name='link'>
        <collision name='collision'>
          <geometry>
            <plane>
              <normal>0 0 1</normal>
              <size>100 100</size>
            </plane>
          </geometry>
          <surface>
            <contact>
              <collide_bitmask>65535</collide_bitmask>
              <ode/>
            </contact>
            <friction>
              <ode>
                <mu>100</mu>
                <mu2>50</mu2>
              </ode>
              <torsional>
                <ode/>
              </torsional>
            </friction>
            <bounce/>
          </surface>
          <max_contacts>10</max_contacts>
        </collision>
        <visual name='visual'>
          <cast_shadows>0</cast_shadows>
          <geometry>
            <plane>
              <normal>0 0 1</normal>
              <size>100 100</size>
            </plane>
          </geometry>
          <material>
            <script>
              <uri>file://media/materials/scripts/gazebo.material</uri>
              <name>Gazebo/Grey</name>
            </script>
          </material>
        </visual>
        <self_collide>0</self_collide>
        <enable_wind>0</enable_wind>
        <kinematic>0</kinematic>
      </link>
    </model>
    <gravity>0 0 -9.8</gravity>
    <magnetic_field>6e-06 2.3e-05 -4.2e-05</magnetic_field>
    <atmosphere type='adiabatic'/>
    <physics type='ode'>
      <max_step_size>0.001</max_step_size>
      <real_time_factor>1</real_time_factor>
      <real_time_update_rate>1000</real_time_update_rate>
    </physics>
    <scene>
      <ambient>0.4 0.4 0.4 1</ambient>
      <background>0.7 0.7 0.7 1</background>
      <shadows>1</shadows>
    </scene>
    <wind/>
    <spherical_coordinates>
      <surface_model>EARTH_WGS84</surface_model>
      <latitude_deg>0</latitude_deg>
      <longitude_deg>0</longitude_deg>
      <elevation>0</elevation>
      <heading_deg>0</heading_deg>
    </spherical_coordinates>
    <model name='table_model'>
      <link name='my_table'>
        <inertial>
          <pose>2 0 0 0 -0 0</pose>
          <mass>1</mass>
          <inertia>
            <ixx>1</ixx>
            <ixy>0</ixy>
            <ixz>0</ixz>
            <iyy>100</iyy>
            <iyz>0</iyz>
            <izz>1</izz>
          </inertia>
        </inertial>
        <collision name='my_table_collision'>
          <pose>2 0 1 0 -0 0</pose>
          <geometry>
            <box>
              <size>1 1 1</size>
            </box>
          </geometry>
          <surface>
            <contact>
              <ode/>
            </contact>
            <friction>
              <ode/>
              <torsional>
                <ode/>
              </torsional>
            </friction>
            <bounce/>
          </surface>
          <max_contacts>10</max_contacts>
        </collision>
        <visual name='my_table_visual'>
          <pose>2 0 1 0 -0 0</pose>
          <geometry>
            <box>
              <size>1 1 1</size>
            </box>
          </geometry>
          <material>
            <script>
              <name>Gazebo/Blue</name>
              <uri>file://media/materials/scripts/gazebo.material</uri>
            </script>
          </material>
        </visual>
        <self_collide>0</self_collide>
        <enable_wind>0</enable_wind>
        <kinematic>0</kinematic>
      </link>
      <pose>0 0 0.01 0 -0 0</pose>
    </model>
    <model name='robot'>
      <link name='robot_base_footprint'>
        <inertial>
          <pose>0.004646 0.000168 0.114874 0 -0 0</pose>
          <mass>25.5448</mass>
          <inertia>
            <ixx>1.42409</ixx>
            <ixy>0.00258412</ixy>
            <ixz>-0.026236</ixz>
            <iyy>6.90962</iyy>
            <iyz>-0.000778086</iyz>
            <izz>6.15668</izz>
          </inertia>
        </inertial>
        <collision name='robot_base_footprint_fixed_joint_lump__robot_base_link_collision'>
          <pose>0 0 0.11 0 -0 0</pose>
          <geometry>
            <mesh>
              <scale>1 1 1</scale>
              <uri>/home/miquel/robot_sim_propio_ws/src/summit_xl_description/meshes/bases/summit_xl_chassis_collision.dae</uri>
            </mesh>
          </geometry>
          <max_contacts>10</max_contacts>
          <surface>
            <contact>
              <ode/>
            </contact>
            <bounce/>
            <friction>
              <torsional>
                <ode/>
              </torsional>
              <ode/>
            </friction>
          </surface>
        </collision>
        <collision name='robot_base_footprint_fixed_joint_lump__robot_j2s6s300_link_base_collision_1'>
          <pose>0.204 0 0.22 0 -0 0</pose>
          <geometry>
            <mesh>
              <scale>1 1 1</scale>
              <uri>/home/miquel/robot_sim_propio_ws/src/kinova_description/meshes/base.dae</uri>
            </mesh>
          </geometry>
          <max_contacts>10</max_contacts>
          <surface>
            <contact>
              <ode/>
            </contact>
            <bounce/>
            <friction>
              <torsional>
                <ode/>
              </torsional>
              <ode/>
            </friction>
          </surface>
        </collision>
        <collision name='robot_base_footprint_fixed_joint_lump__robot_front_rgbd_camera_link_collision_2'>
          <pose>0.3267 0.012 0.2965 0 -0 0</pose>
          <geometry>
            <box>
              <size>0.026 0.124 0.029</size>
            </box>
          </geometry>
          <surface>
            <contact>
              <ode>
                <kp>1e+13</kp>
                <kd>1</kd>
              </ode>
            </contact>
            <friction>
              <ode>
                <mu2>1</mu2>
                <fdir1>0 0 0</fdir1>
              </ode>
              <torsional>
                <ode/>
              </torsional>
            </friction>
            <bounce/>
          </surface>
          <max_contacts>10</max_contacts>
        </collision>
        <visual name='robot_base_footprint_visual'>
          <pose>0 0 0 0 -0 0</pose>
          <geometry>
            <box>
              <size>0.001 0.001 0.001</size>
            </box>
          </geometry>
        </visual>
        <visual name='robot_base_footprint_fixed_joint_lump__robot_base_link_visual_1'>
          <pose>0 0 0.11 0 -0 0</pose>
          <geometry>
            <mesh>
              <scale>1 1 1</scale>
              <uri>/home/miquel/robot_sim_propio_ws/src/summit_xl_description/meshes/bases/summit_xl_chassis.dae</uri>
            </mesh>
          </geometry>
        </visual>
        <visual name='robot_base_footprint_fixed_joint_lump__robot_j2s6s300_link_base_visual_2'>
          <pose>0.204 0 0.22 0 -0 0</pose>
          <geometry>
            <mesh>
              <scale>1 1 1</scale>
              <uri>/home/miquel/robot_sim_propio_ws/src/kinova_description/meshes/base.dae</uri>
            </mesh>
          </geometry>
        </visual>
        <visual name='robot_base_footprint_fixed_joint_lump__robot_front_rgbd_camera_link_visual_3'>
          <pose>0.3398 0.012 0.2965 1.5708 -0 1.5708</pose>
          <geometry>
            <mesh>
              <scale>1 1 1</scale>
              <uri>/home/miquel/robot_sim_propio_ws/src/robotnik_sensors/meshes/intel_d435.dae</uri>
            </mesh>
          </geometry>
        </visual>
        <visual name='robot_base_footprint_fixed_joint_lump__robot_imu_link_visual_4'>
          <pose>-0.18 0 0.28 0 -0 0</pose>
          <geometry>
            <box>
              <size>0.001 0.001 0.001</size>
            </box>
          </geometry>
        </visual>
        <self_collide>0</self_collide>
        <enable_wind>0</enable_wind>
        <kinematic>0</kinematic>
        <gravity>1</gravity>
        <sensor name='robotcolor' type='camera'>
          <camera name='robot'>
            <horizontal_fov>1.21126</horizontal_fov>
            <image>
              <width>1920</width>
              <height>1080</height>
              <format>RGB_INT8</format>
            </image>
            <clip>
              <near>0.1</near>
              <far>100</far>
            </clip>
            <noise>
              <type>gaussian</type>
              <mean>0</mean>
              <stddev>0.007</stddev>
            </noise>
          </camera>
          <always_on>1</always_on>
          <update_rate>7</update_rate>
          <visualize>0</visualize>
          <plugin name='robot_front_rgbd_camerakortex_vision_controller' filename='libgazebo_ros_camera.so'>
            <alwaysOn>1</alwaysOn>
            <updateRate>7</updateRate>
            <cameraName>robot_color</cameraName>
            <imageTopicName>/robot/front_rgbd_camera/rgb/image_raw</imageTopicName>
            <cameraInfoTopicName>/robot/front_rgbd_camera/rgb/camera_info</cameraInfoTopicName>
            <frameName>/robot_front_rgbd_camera_color_optical_frame</frameName>
            <hackBaseline>0.07</hackBaseline>
            <distortionK1>0.0</distortionK1>
            <distortionK2>0.0</distortionK2>
            <distortionK3>0.0</distortionK3>
            <distortionT1>0.0</distortionT1>
            <distortionT2>0.0</distortionT2>
            <ignoreTfPrefix>1</ignoreTfPrefix>
            <robotNamespace>/</robotNamespace>
          </plugin>
          <pose>0.33515 0.0595 0.2965 0 -0 0</pose>
        </sensor>
        <sensor name='robotired1' type='camera'>
          <camera name='robot'>
            <horizontal_fov>1.48702</horizontal_fov>
            <image>
              <width>1280</width>
              <height>720</height>
              <format>L_INT8</format>
            </image>
            <clip>
              <near>0.1</near>
              <far>100</far>
            </clip>
            <noise>
              <type>gaussian</type>
              <mean>0</mean>
              <stddev>0.05</stddev>
            </noise>
          </camera>
          <always_on>1</always_on>
          <update_rate>7</update_rate>
          <visualize>0</visualize>
          <pose>0.33515 0.0595 0.2965 0 -0 0</pose>
        </sensor>
        <sensor name='robotired2' type='camera'>
          <camera name='robot'>
            <horizontal_fov>1.48702</horizontal_fov>
            <image>
              <width>1280</width>
              <height>720</height>
              <format>L_INT8</format>
            </image>
            <clip>
              <near>0.1</near>
              <far>100</far>
            </clip>
            <noise>
              <type>gaussian</type>
              <mean>0</mean>
              <stddev>0.05</stddev>
            </noise>
          </camera>
          <always_on>1</always_on>
          <update_rate>7</update_rate>
          <visualize>0</visualize>
          <pose>0.33515 0.0595 0.2965 0 -0 0</pose>
        </sensor>
        <sensor name='robotdepth' type='depth'>
          <camera name='robot'>
            <horizontal_fov>1.48702</horizontal_fov>
            <image>
              <width>1280</width>
              <height>720</height>
            </image>
            <clip>
              <near>0.1</near>
              <far>100</far>
            </clip>
            <noise>
              <type>gaussian</type>
              <mean>0</mean>
              <stddev>0.1</stddev>
            </noise>
          </camera>
          <always_on>0</always_on>
          <update_rate>7</update_rate>
          <visualize>0</visualize>
          <plugin name='robot_front_depth_controller' filename='libgazebo_ros_depth_camera.so'>
            <alwaysOn>1</alwaysOn>
            <updateRate>0</updateRate>
            <cameraName>robot_depth</cameraName>
            <imageTopicName>/robot/front_depth_camera/image_raw</imageTopicName>
            <cameraInfoTopicName>/robot/front_depth_camera/camera_info</cameraInfoTopicName>
            <frameName>/robot_front_rgbd_camera_color_optical_frame</frameName>
            <distortionK1>0.0</distortionK1>
            <distortionK2>0.0</distortionK2>
            <distortionK3>0.0</distortionK3>
            <distortionT1>0.0</distortionT1>
            <distortionT2>0.0</distortionT2>
            <ignoreTfPrefix>1</ignoreTfPrefix>
            <robotNamespace>/</robotNamespace>
          </plugin>
          <pose>0.33515 0.0595 0.2965 0 -0 0</pose>
        </sensor>
        <gravity>1</gravity>
        <sensor name='robot_imu_imu_sensor' type='imu'>
          <always_on>1</always_on>
          <update_rate>100</update_rate>
          <visualize>1</visualize>
          <topic>__default_topic__</topic>
          <plugin name='robot_imu_imu_plugin' filename='libgazebo_ros_imu_sensor.so'>
            <topicName>imu/data</topicName>
            <bodyName>robot_imu_link</bodyName>
            <updateRateHZ>100.0</updateRateHZ>
            <gaussianNoise>0.0</gaussianNoise>
            <xyzOffset>0 0 0</xyzOffset>
            <rpyOffset>0 0 0</rpyOffset>
            <frameName>robot_imu_link</frameName>
            <robotNamespace>/</robotNamespace>
          </plugin>
          <pose>-0.18 0 0.28 0 -0 0</pose>
          <imu/>
        </sensor>
      </link>
      <joint name='robot_j2s6s300_joint_1' type='revolute'>
        <pose relative_to='robot_base_footprint'>0.204 0 0.37675 3.14159 -0 3.14159</pose>
        <parent>robot_base_footprint</parent>
        <child>robot_j2s6s300_link_1</child>
        <axis>
          <xyz>0 0 1</xyz>
          <limit>
            <effort>40</effort>
            <velocity>0.628319</velocity>
            <lower>-1e+16</lower>
            <upper>1e+16</upper>
          </limit>
          <dynamics>
            <damping>0</damping>
            <friction>0</friction>
            <spring_reference>0</spring_reference>
            <spring_stiffness>0</spring_stiffness>
          </dynamics>
        </axis>
        <physics>
          <provide_feedback>1</provide_feedback>
          <ode>
            <limit>
              <cfm>0</cfm>
              <erp>0.2</erp>
            </limit>
            <provide_feedback>1</provide_feedback>
          </ode>
        </physics>
      </joint>
      <link name='robot_j2s6s300_link_1'>
        <pose relative_to='robot_j2s6s300_joint_1'>0 0 0 0 -0 0</pose>
        <inertial>
          <pose>0 -0.002 -0.0605 0 -0 0</pose>
          <mass>0.7477</mass>
          <inertia>
            <ixx>0.00152032</ixx>
            <ixy>0</ixy>
            <ixz>0</ixz>
            <iyy>0.00152032</iyy>
            <iyz>0</iyz>
            <izz>0.00059816</izz>
          </inertia>
        </inertial>
        <collision name='robot_j2s6s300_link_1_collision'>
          <pose>0 0 0 0 -0 0</pose>
          <geometry>
            <mesh>
              <scale>1 1 1</scale>
              <uri>/home/miquel/robot_sim_propio_ws/src/kinova_description/meshes/shoulder.dae</uri>
            </mesh>
          </geometry>
          <max_contacts>10</max_contacts>
          <surface>
            <contact>
              <ode/>
            </contact>
            <bounce/>
            <friction>
              <torsional>
                <ode/>
              </torsional>
              <ode/>
            </friction>
          </surface>
        </collision>
        <visual name='robot_j2s6s300_link_1_visual'>
          <pose>0 0 0 0 -0 0</pose>
          <geometry>
            <mesh>
              <scale>1 1 1</scale>
              <uri>/home/miquel/robot_sim_propio_ws/src/kinova_description/meshes/shoulder.dae</uri>
            </mesh>
          </geometry>
        </visual>
        <visual name='robot_j2s6s300_link_1_visual_1'>
          <pose>0 0 0 0 -0 0</pose>
          <geometry>
            <mesh>
              <scale>1 1 1</scale>
              <uri>/home/miquel/robot_sim_propio_ws/src/kinova_description/meshes/ring_big.dae</uri>
            </mesh>
          </geometry>
        </visual>
        <self_collide>0</self_collide>
        <enable_wind>0</enable_wind>
        <kinematic>0</kinematic>
      </link>
      <joint name='robot_j2s6s300_joint_2' type='revolute'>
        <pose relative_to='robot_j2s6s300_link_1'>0 0.0016 -0.11875 -1.5708 -0 3.14159</pose>
        <parent>robot_j2s6s300_link_1</parent>
        <child>robot_j2s6s300_link_2</child>
        <axis>
          <xyz>0 0 1</xyz>
          <limit>
            <lower>0.820305</lower>
            <upper>5.46288</upper>
            <effort>80</effort>
            <velocity>0.628319</velocity>
          </limit>
          <dynamics>
            <damping>0</damping>
            <friction>0</friction>
            <spring_reference>0</spring_reference>
            <spring_stiffness>0</spring_stiffness>
          </dynamics>
        </axis>
        <physics>
          <provide_feedback>1</provide_feedback>
          <ode>
            <limit>
              <cfm>0</cfm>
              <erp>0.2</erp>
            </limit>
            <provide_feedback>1</provide_feedback>
          </ode>
        </physics>
      </joint>
      <link name='robot_j2s6s300_link_2'>
        <pose relative_to='robot_j2s6s300_joint_2'>0 0 0 0 -0 0</pose>
        <inertial>
          <pose>0 -0.2065 -0.01 0 -0 0</pose>
          <mass>0.99</mass>
          <inertia>
            <ixx>0.0105022</ixx>
            <ixy>0</ixy>
            <ixz>0</ixz>
            <iyy>0.000792</iyy>
            <iyz>0</iyz>
            <izz>0.0105022</izz>
          </inertia>
        </inertial>
        <collision name='robot_j2s6s300_link_2_collision'>
          <pose>0 0 0 0 -0 0</pose>
          <geometry>
            <mesh>
              <scale>1 1 1</scale>
              <uri>/home/miquel/robot_sim_propio_ws/src/kinova_description/meshes/arm.dae</uri>
            </mesh>
          </geometry>
          <max_contacts>10</max_contacts>
          <surface>
            <contact>
              <ode/>
            </contact>
            <bounce/>
            <friction>
              <torsional>
                <ode/>
              </torsional>
              <ode/>
            </friction>
          </surface>
        </collision>
        <visual name='robot_j2s6s300_link_2_visual'>
          <pose>0 0 0 0 -0 0</pose>
          <geometry>
            <mesh>
              <scale>1 1 1</scale>
              <uri>/home/miquel/robot_sim_propio_ws/src/kinova_description/meshes/arm.dae</uri>
            </mesh>
          </geometry>
        </visual>
        <visual name='robot_j2s6s300_link_2_visual_1'>
          <pose>0 0 0 0 -0 0</pose>
          <geometry>
            <mesh>
              <scale>1 1 1</scale>
              <uri>/home/miquel/robot_sim_propio_ws/src/kinova_description/meshes/ring_big.dae</uri>
            </mesh>
          </geometry>
        </visual>
        <self_collide>0</self_collide>
        <enable_wind>0</enable_wind>
        <kinematic>0</kinematic>
      </link>
      <joint name='robot_j2s6s300_joint_3' type='revolute'>
        <pose relative_to='robot_j2s6s300_link_2'>0 -0.41 0 3.14159 -0 3.14159</pose>
        <parent>robot_j2s6s300_link_2</parent>
        <child>robot_j2s6s300_link_3</child>
        <axis>
          <xyz>0 0 1</xyz>
          <limit>
            <lower>0.331613</lower>
            <upper>5.95157</upper>
            <effort>40</effort>
            <velocity>0.628319</velocity>
          </limit>
          <dynamics>
            <damping>0</damping>
            <friction>0</friction>
            <spring_reference>0</spring_reference>
            <spring_stiffness>0</spring_stiffness>
          </dynamics>
        </axis>
        <physics>
          <provide_feedback>1</provide_feedback>
          <ode>
            <limit>
              <cfm>0</cfm>
              <erp>0.2</erp>
            </limit>
            <provide_feedback>1</provide_feedback>
          </ode>
        </physics>
      </joint>
      <link name='robot_j2s6s300_link_3'>
        <pose relative_to='robot_j2s6s300_joint_3'>0 0 0 0 -0 0</pose>
        <inertial>
          <pose>0 0.081 -0.0086 0 -0 0</pose>
          <mass>0.6763</mass>
          <inertia>
            <ixx>0.00142022</ixx>
            <ixy>0</ixy>
            <ixz>0</ixz>
            <iyy>0.000304335</iyy>
            <iyz>0</iyz>
            <izz>0.00142022</izz>
          </inertia>
        </inertial>
        <collision name='robot_j2s6s300_link_3_collision'>
          <pose>0 0 0 0 -0 0</pose>
          <geometry>
            <mesh>
              <scale>1 1 1</scale>
              <uri>/home/miquel/robot_sim_propio_ws/src/kinova_description/meshes/forearm.dae</uri>
            </mesh>
          </geometry>
          <max_contacts>10</max_contacts>
          <surface>
            <contact>
              <ode/>
            </contact>
            <bounce/>
            <friction>
              <torsional>
                <ode/>
              </torsional>
              <ode/>
            </friction>
          </surface>
        </collision>
        <visual name='robot_j2s6s300_link_3_visual'>
          <pose>0 0 0 0 -0 0</pose>
          <geometry>
            <mesh>
              <scale>1 1 1</scale>
              <uri>/home/miquel/robot_sim_propio_ws/src/kinova_description/meshes/forearm.dae</uri>
            </mesh>
          </geometry>
        </visual>
        <visual name='robot_j2s6s300_link_3_visual_1'>
          <pose>0 0 0 0 -0 0</pose>
          <geometry>
            <mesh>
              <scale>1 1 1</scale>
              <uri>/home/miquel/robot_sim_propio_ws/src/kinova_description/meshes/ring_big.dae</uri>
            </mesh>
          </geometry>
        </visual>
        <self_collide>0</self_collide>
        <enable_wind>0</enable_wind>
        <kinematic>0</kinematic>
      </link>
      <joint name='robot_j2s6s300_joint_4' type='revolute'>
        <pose relative_to='robot_j2s6s300_link_3'>0 0.2073 -0.0114 -1.5708 -0 3.14159</pose>
        <parent>robot_j2s6s300_link_3</parent>
        <child>robot_j2s6s300_link_4</child>
        <axis>
          <xyz>0 0 1</xyz>
          <limit>
            <effort>20</effort>
            <velocity>0.837758</velocity>
            <lower>-1e+16</lower>
            <upper>1e+16</upper>
          </limit>
          <dynamics>
            <damping>0</damping>
            <friction>0</friction>
            <spring_reference>0</spring_reference>
            <spring_stiffness>0</spring_stiffness>
          </dynamics>
        </axis>
        <physics>
          <provide_feedback>1</provide_feedback>
          <ode>
            <limit>
              <cfm>0</cfm>
              <erp>0.2</erp>
            </limit>
            <provide_feedback>1</provide_feedback>
          </ode>
        </physics>
      </joint>
      <link name='robot_j2s6s300_link_4'>
        <pose relative_to='robot_j2s6s300_joint_4'>0 0 0 0 -0 0</pose>
        <inertial>
          <pose>0 0.002885 -0.054193 0 -0 0</pose>
          <mass>0.463</mass>
          <inertia>
            <ixx>0.000432132</ixx>
            <ixy>0</ixy>
            <ixz>0</ixz>
            <iyy>0.000432132</iyy>
            <iyz>0</iyz>
            <izz>9.26e-05</izz>
          </inertia>
        </inertial>
        <collision name='robot_j2s6s300_link_4_collision'>
          <pose>0 0 0 0 -0 0</pose>
          <geometry>
            <mesh>
              <scale>1 1 1</scale>
              <uri>/home/miquel/robot_sim_propio_ws/src/kinova_description/meshes/wrist_spherical_1.dae</uri>
            </mesh>
          </geometry>
          <max_contacts>10</max_contacts>
          <surface>
            <contact>
              <ode/>
            </contact>
            <bounce/>
            <friction>
              <torsional>
                <ode/>
              </torsional>
              <ode/>
            </friction>
          </surface>
        </collision>
        <visual name='robot_j2s6s300_link_4_visual'>
          <pose>0 0 0 0 -0 0</pose>
          <geometry>
            <mesh>
              <scale>1 1 1</scale>
              <uri>/home/miquel/robot_sim_propio_ws/src/kinova_description/meshes/wrist_spherical_1.dae</uri>
            </mesh>
          </geometry>
        </visual>
        <visual name='robot_j2s6s300_link_4_visual_1'>
          <pose>0 0 0 0 -0 0</pose>
          <geometry>
            <mesh>
              <scale>1 1 1</scale>
              <uri>/home/miquel/robot_sim_propio_ws/src/kinova_description/meshes/ring_small.dae</uri>
            </mesh>
          </geometry>
        </visual>
        <self_collide>0</self_collide>
        <enable_wind>0</enable_wind>
        <kinematic>0</kinematic>
      </link>
      <joint name='robot_j2s6s300_joint_5' type='revolute'>
        <pose relative_to='robot_j2s6s300_link_4'>0 0 -0.10375 1.5708 -0 3.14159</pose>
        <parent>robot_j2s6s300_link_4</parent>
        <child>robot_j2s6s300_link_5</child>
        <axis>
          <xyz>0 0 1</xyz>
          <limit>
            <lower>0.523599</lower>
            <upper>5.75959</upper>
            <effort>20</effort>
            <velocity>0.837758</velocity>
          </limit>
          <dynamics>
            <damping>0</damping>
            <friction>0</friction>
            <spring_reference>0</spring_reference>
            <spring_stiffness>0</spring_stiffness>
          </dynamics>
        </axis>
        <physics>
          <provide_feedback>1</provide_feedback>
          <ode>
            <limit>
              <cfm>0</cfm>
              <erp>0.2</erp>
            </limit>
            <provide_feedback>1</provide_feedback>
          </ode>
        </physics>
      </joint>
      <link name='robot_j2s6s300_link_5'>
        <pose relative_to='robot_j2s6s300_joint_5'>0 0 0 0 -0 0</pose>
        <inertial>
          <pose>0 0.049721 -0.002856 0 -0 0</pose>
          <mass>0.463</mass>
          <inertia>
            <ixx>0.000432132</ixx>
            <ixy>0</ixy>
            <ixz>0</ixz>
            <iyy>9.26e-05</iyy>
            <iyz>0</iyz>
            <izz>0.000432132</izz>
          </inertia>
        </inertial>
        <collision name='robot_j2s6s300_link_5_collision'>
          <pose>0 0 0 0 -0 0</pose>
          <geometry>
            <mesh>
              <scale>1 1 1</scale>
              <uri>/home/miquel/robot_sim_propio_ws/src/kinova_description/meshes/wrist_spherical_2.dae</uri>
            </mesh>
          </geometry>
          <max_contacts>10</max_contacts>
          <surface>
            <contact>
              <ode/>
            </contact>
            <bounce/>
            <friction>
              <torsional>
                <ode/>
              </torsional>
              <ode/>
            </friction>
          </surface>
        </collision>
        <visual name='robot_j2s6s300_link_5_visual'>
          <pose>0 0 0 0 -0 0</pose>
          <geometry>
            <mesh>
              <scale>1 1 1</scale>
              <uri>/home/miquel/robot_sim_propio_ws/src/kinova_description/meshes/wrist_spherical_2.dae</uri>
            </mesh>
          </geometry>
        </visual>
        <visual name='robot_j2s6s300_link_5_visual_1'>
          <pose>0 0 0 0 -0 0</pose>
          <geometry>
            <mesh>
              <scale>1 1 1</scale>
              <uri>/home/miquel/robot_sim_propio_ws/src/kinova_description/meshes/ring_small.dae</uri>
            </mesh>
          </geometry>
        </visual>
        <self_collide>0</self_collide>
        <enable_wind>0</enable_wind>
        <kinematic>0</kinematic>
      </link>
      <joint name='robot_j2s6s300_joint_6' type='revolute'>
        <pose relative_to='robot_j2s6s300_link_5'>0 0.10375 0 -1.5708 -0 3.14159</pose>
        <parent>robot_j2s6s300_link_5</parent>
        <child>robot_j2s6s300_link_6</child>
        <axis>
          <xyz>0 0 1</xyz>
          <limit>
            <effort>20</effort>
            <velocity>0.837758</velocity>
            <lower>-1e+16</lower>
            <upper>1e+16</upper>
          </limit>
          <dynamics>
            <damping>0</damping>
            <friction>0</friction>
            <spring_reference>0</spring_reference>
            <spring_stiffness>0</spring_stiffness>
          </dynamics>
        </axis>
        <physics>
          <provide_feedback>1</provide_feedback>
          <ode>
            <limit>
              <cfm>0</cfm>
              <erp>0.2</erp>
            </limit>
            <provide_feedback>1</provide_feedback>
          </ode>
        </physics>
      </joint>
      <link name='robot_j2s6s300_link_6'>
        <pose relative_to='robot_j2s6s300_joint_6'>0 0 0 0 -0 0</pose>
        <inertial>
          <pose>0 0 -0.06 0 -0 0</pose>
          <mass>0.99</mass>
          <inertia>
            <ixx>0.000345324</ixx>
            <ixy>0</ixy>
            <ixz>0</ixz>
            <iyy>0.000345324</iyy>
            <iyz>0</iyz>
            <izz>0.0005816</izz>
          </inertia>
        </inertial>
        <collision name='robot_j2s6s300_link_6_collision'>
          <pose>0 0 0 0 -0 0</pose>
          <geometry>
            <mesh>
              <scale>1 1 1</scale>
              <uri>/home/miquel/robot_sim_propio_ws/src/kinova_description/meshes/hand_3finger.dae</uri>
            </mesh>
          </geometry>
          <max_contacts>10</max_contacts>
          <surface>
            <contact>
              <ode/>
            </contact>
            <bounce/>
            <friction>
              <torsional>
                <ode/>
              </torsional>
              <ode/>
            </friction>
          </surface>
        </collision>
        <visual name='robot_j2s6s300_link_6_visual'>
          <pose>0 0 0 0 -0 0</pose>
          <geometry>
            <mesh>
              <scale>1 1 1</scale>
              <uri>/home/miquel/robot_sim_propio_ws/src/kinova_description/meshes/hand_3finger.dae</uri>
            </mesh>
          </geometry>
        </visual>
        <visual name='robot_j2s6s300_link_6_visual_1'>
          <pose>0 0 0 0 -0 0</pose>
          <geometry>
            <mesh>
              <scale>1 1 1</scale>
              <uri>/home/miquel/robot_sim_propio_ws/src/kinova_description/meshes/ring_small.dae</uri>
            </mesh>
          </geometry>
        </visual>
        <self_collide>0</self_collide>
        <enable_wind>0</enable_wind>
        <kinematic>0</kinematic>
      </link>
      <joint name='robot_j2s6s300_joint_finger_1' type='revolute'>
        <pose relative_to='robot_j2s6s300_link_6'>0.00279 0.03126 -0.11467 -1.5708 0.649262 1.35961</pose>
        <parent>robot_j2s6s300_link_6</parent>
        <child>robot_j2s6s300_link_finger_1</child>
        <axis>
          <xyz>0 0 1</xyz>
          <limit>
            <lower>0</lower>
            <upper>1.51</upper>
            <effort>2</effort>
            <velocity>1</velocity>
          </limit>
          <dynamics>
            <spring_reference>0</spring_reference>
            <spring_stiffness>0</spring_stiffness>
          </dynamics>
        </axis>
      </joint>
      <link name='robot_j2s6s300_link_finger_1'>
        <pose relative_to='robot_j2s6s300_joint_finger_1'>0 0 0 0 -0 0</pose>
        <inertial>
          <pose>0.022 0 0 0 -0 0</pose>
          <mass>0.01</mass>
          <inertia>
            <ixx>7.89997e-07</ixx>
            <ixy>0</ixy>
            <ixz>0</ixz>
            <iyy>7.89997e-07</iyy>
            <iyz>0</iyz>
            <izz>8e-08</izz>
          </inertia>
        </inertial>
        <collision name='robot_j2s6s300_link_finger_1_collision'>
          <pose>0 0 0 0 -0 0</pose>
          <geometry>
            <mesh>
              <scale>1 1 1</scale>
              <uri>/home/miquel/robot_sim_propio_ws/src/kinova_description/meshes/finger_proximal.dae</uri>
            </mesh>
          </geometry>
          <max_contacts>10</max_contacts>
          <surface>
            <contact>
              <ode/>
            </contact>
            <bounce/>
            <friction>
              <torsional>
                <ode/>
              </torsional>
              <ode/>
            </friction>
          </surface>
        </collision>
        <visual name='robot_j2s6s300_link_finger_1_visual'>
          <pose>0 0 0 0 -0 0</pose>
          <geometry>
            <mesh>
              <scale>1 1 1</scale>
              <uri>/home/miquel/robot_sim_propio_ws/src/kinova_description/meshes/finger_proximal.dae</uri>
            </mesh>
          </geometry>
        </visual>
        <self_collide>0</self_collide>
        <enable_wind>0</enable_wind>
        <kinematic>0</kinematic>
      </link>
      <joint name='robot_j2s6s300_joint_finger_tip_1' type='revolute'>
        <pose relative_to='robot_j2s6s300_link_finger_1'>0.044 -0.003 0 0 -0 0</pose>
        <parent>robot_j2s6s300_link_finger_1</parent>
        <child>robot_j2s6s300_link_finger_tip_1</child>
        <axis>
          <xyz>0 0 1</xyz>
          <limit>
            <lower>0.8</lower>
            <upper>1.2</upper>
            <effort>2</effort>
            <velocity>1</velocity>
          </limit>
          <dynamics>
            <spring_reference>0</spring_reference>
            <spring_stiffness>0</spring_stiffness>
          </dynamics>
        </axis>
      </joint>
      <link name='robot_j2s6s300_link_finger_tip_1'>
        <pose relative_to='robot_j2s6s300_joint_finger_tip_1'>0 0 0 0 -0 0</pose>
        <inertial>
          <pose>0.022 0 0 0 -0 0</pose>
          <mass>0.01</mass>
          <inertia>
            <ixx>7.89997e-07</ixx>
            <ixy>0</ixy>
            <ixz>0</ixz>
            <iyy>7.89997e-07</iyy>
            <iyz>0</iyz>
            <izz>8e-08</izz>
          </inertia>
        </inertial>
        <collision name='robot_j2s6s300_link_finger_tip_1_collision'>
          <pose>0 0 0 0 -0 0</pose>
          <geometry>
            <mesh>
              <scale>1 1 1</scale>
              <uri>/home/miquel/robot_sim_propio_ws/src/kinova_description/meshes/finger_distal.dae</uri>
            </mesh>
          </geometry>
          <max_contacts>10</max_contacts>
          <surface>
            <contact>
              <ode/>
            </contact>
            <bounce/>
            <friction>
              <torsional>
                <ode/>
              </torsional>
              <ode/>
            </friction>
          </surface>
        </collision>
        <visual name='robot_j2s6s300_link_finger_tip_1_visual'>
          <pose>0 0 0 0 -0 0</pose>
          <geometry>
            <mesh>
              <scale>1 1 1</scale>
              <uri>/home/miquel/robot_sim_propio_ws/src/kinova_description/meshes/finger_distal.dae</uri>
            </mesh>
          </geometry>
        </visual>
        <self_collide>0</self_collide>
        <enable_wind>0</enable_wind>
        <kinematic>0</kinematic>
      </link>
      <joint name='robot_j2s6s300_joint_finger_2' type='revolute'>
        <pose relative_to='robot_j2s6s300_link_6'>0.02226 -0.02707 -0.11482 -1.5708 0.649262 -1.38614</pose>
        <parent>robot_j2s6s300_link_6</parent>
        <child>robot_j2s6s300_link_finger_2</child>
        <axis>
          <xyz>0 0 1</xyz>
          <limit>
            <lower>0</lower>
            <upper>1.51</upper>
            <effort>2</effort>
            <velocity>1</velocity>
          </limit>
          <dynamics>
            <spring_reference>0</spring_reference>
            <spring_stiffness>0</spring_stiffness>
          </dynamics>
        </axis>
      </joint>
      <link name='robot_j2s6s300_link_finger_2'>
        <pose relative_to='robot_j2s6s300_joint_finger_2'>0 0 0 0 -0 0</pose>
        <inertial>
          <pose>0.022 0 0 0 -0 0</pose>
          <mass>0.01</mass>
          <inertia>
            <ixx>7.89997e-07</ixx>
            <ixy>0</ixy>
            <ixz>0</ixz>
            <iyy>7.89997e-07</iyy>
            <iyz>0</iyz>
            <izz>8e-08</izz>
          </inertia>
        </inertial>
        <collision name='robot_j2s6s300_link_finger_2_collision'>
          <pose>0 0 0 0 -0 0</pose>
          <geometry>
            <mesh>
              <scale>1 1 1</scale>
              <uri>/home/miquel/robot_sim_propio_ws/src/kinova_description/meshes/finger_proximal.dae</uri>
            </mesh>
          </geometry>
          <max_contacts>10</max_contacts>
          <surface>
            <contact>
              <ode/>
            </contact>
            <bounce/>
            <friction>
              <torsional>
                <ode/>
              </torsional>
              <ode/>
            </friction>
          </surface>
        </collision>
        <visual name='robot_j2s6s300_link_finger_2_visual'>
          <pose>0 0 0 0 -0 0</pose>
          <geometry>
            <mesh>
              <scale>1 1 1</scale>
              <uri>/home/miquel/robot_sim_propio_ws/src/kinova_description/meshes/finger_proximal.dae</uri>
            </mesh>
          </geometry>
        </visual>
        <self_collide>0</self_collide>
        <enable_wind>0</enable_wind>
        <kinematic>0</kinematic>
      </link>
      <joint name='robot_j2s6s300_joint_finger_tip_2' type='revolute'>
        <pose relative_to='robot_j2s6s300_link_finger_2'>0.044 -0.003 0 0 -0 0</pose>
        <parent>robot_j2s6s300_link_finger_2</parent>
        <child>robot_j2s6s300_link_finger_tip_2</child>
        <axis>
          <xyz>0 0 1</xyz>
          <limit>
            <lower>0.8</lower>
            <upper>1.2</upper>
            <effort>2</effort>
            <velocity>1</velocity>
          </limit>
          <dynamics>
            <spring_reference>0</spring_reference>
            <spring_stiffness>0</spring_stiffness>
          </dynamics>
        </axis>
      </joint>
      <link name='robot_j2s6s300_link_finger_tip_2'>
        <pose relative_to='robot_j2s6s300_joint_finger_tip_2'>0 0 0 0 -0 0</pose>
        <inertial>
          <pose>0.022 0 0 0 -0 0</pose>
          <mass>0.01</mass>
          <inertia>
            <ixx>7.89997e-07</ixx>
            <ixy>0</ixy>
            <ixz>0</ixz>
            <iyy>7.89997e-07</iyy>
            <iyz>0</iyz>
            <izz>8e-08</izz>
          </inertia>
        </inertial>
        <collision name='robot_j2s6s300_link_finger_tip_2_collision'>
          <pose>0 0 0 0 -0 0</pose>
          <geometry>
            <mesh>
              <scale>1 1 1</scale>
              <uri>/home/miquel/robot_sim_propio_ws/src/kinova_description/meshes/finger_distal.dae</uri>
            </mesh>
          </geometry>
          <max_contacts>10</max_contacts>
          <surface>
            <contact>
              <ode/>
            </contact>
            <bounce/>
            <friction>
              <torsional>
                <ode/>
              </torsional>
              <ode/>
            </friction>
          </surface>
        </collision>
        <visual name='robot_j2s6s300_link_finger_tip_2_visual'>
          <pose>0 0 0 0 -0 0</pose>
          <geometry>
            <mesh>
              <scale>1 1 1</scale>
              <uri>/home/miquel/robot_sim_propio_ws/src/kinova_description/meshes/finger_distal.dae</uri>
            </mesh>
          </geometry>
        </visual>
        <self_collide>0</self_collide>
        <enable_wind>0</enable_wind>
        <kinematic>0</kinematic>
      </link>
      <joint name='robot_j2s6s300_joint_finger_3' type='revolute'>
        <pose relative_to='robot_j2s6s300_link_6'>-0.02226 -0.02707 -0.11482 -1.5708 0.649262 -1.75545</pose>
        <parent>robot_j2s6s300_link_6</parent>
        <child>robot_j2s6s300_link_finger_3</child>
        <axis>
          <xyz>0 0 1</xyz>
          <limit>
            <lower>0</lower>
            <upper>1.51</upper>
            <effort>2</effort>
            <velocity>1</velocity>
          </limit>
          <dynamics>
            <spring_reference>0</spring_reference>
            <spring_stiffness>0</spring_stiffness>
          </dynamics>
        </axis>
      </joint>
      <link name='robot_j2s6s300_link_finger_3'>
        <pose relative_to='robot_j2s6s300_joint_finger_3'>0 0 0 0 -0 0</pose>
        <inertial>
          <pose>0.022 0 0 0 -0 0</pose>
          <mass>0.01</mass>
          <inertia>
            <ixx>7.89997e-07</ixx>
            <ixy>0</ixy>
            <ixz>0</ixz>
            <iyy>7.89997e-07</iyy>
            <iyz>0</iyz>
            <izz>8e-08</izz>
          </inertia>
        </inertial>
        <collision name='robot_j2s6s300_link_finger_3_collision'>
          <pose>0 0 0 0 -0 0</pose>
          <geometry>
            <mesh>
              <scale>1 1 1</scale>
              <uri>/home/miquel/robot_sim_propio_ws/src/kinova_description/meshes/finger_proximal.dae</uri>
            </mesh>
          </geometry>
          <max_contacts>10</max_contacts>
          <surface>
            <contact>
              <ode/>
            </contact>
            <bounce/>
            <friction>
              <torsional>
                <ode/>
              </torsional>
              <ode/>
            </friction>
          </surface>
        </collision>
        <visual name='robot_j2s6s300_link_finger_3_visual'>
          <pose>0 0 0 0 -0 0</pose>
          <geometry>
            <mesh>
              <scale>1 1 1</scale>
              <uri>/home/miquel/robot_sim_propio_ws/src/kinova_description/meshes/finger_proximal.dae</uri>
            </mesh>
          </geometry>
        </visual>
        <self_collide>0</self_collide>
        <enable_wind>0</enable_wind>
        <kinematic>0</kinematic>
      </link>
      <joint name='robot_j2s6s300_joint_finger_tip_3' type='revolute'>
        <pose relative_to='robot_j2s6s300_link_finger_3'>0.044 -0.003 0 0 -0 0</pose>
        <parent>robot_j2s6s300_link_finger_3</parent>
        <child>robot_j2s6s300_link_finger_tip_3</child>
        <axis>
          <xyz>0 0 1</xyz>
          <limit>
            <lower>0.8</lower>
            <upper>1.2</upper>
            <effort>2</effort>
            <velocity>1</velocity>
          </limit>
          <dynamics>
            <spring_reference>0</spring_reference>
            <spring_stiffness>0</spring_stiffness>
          </dynamics>
        </axis>
      </joint>
      <link name='robot_j2s6s300_link_finger_tip_3'>
        <pose relative_to='robot_j2s6s300_joint_finger_tip_3'>0 0 0 0 -0 0</pose>
        <inertial>
          <pose>0.022 0 0 0 -0 0</pose>
          <mass>0.01</mass>
          <inertia>
            <ixx>7.89997e-07</ixx>
            <ixy>0</ixy>
            <ixz>0</ixz>
            <iyy>7.89997e-07</iyy>
            <iyz>0</iyz>
            <izz>8e-08</izz>
          </inertia>
        </inertial>
        <collision name='robot_j2s6s300_link_finger_tip_3_collision'>
          <pose>0 0 0 0 -0 0</pose>
          <geometry>
            <mesh>
              <scale>1 1 1</scale>
              <uri>/home/miquel/robot_sim_propio_ws/src/kinova_description/meshes/finger_distal.dae</uri>
            </mesh>
          </geometry>
          <max_contacts>10</max_contacts>
          <surface>
            <contact>
              <ode/>
            </contact>
            <bounce/>
            <friction>
              <torsional>
                <ode/>
              </torsional>
              <ode/>
            </friction>
          </surface>
        </collision>
        <visual name='robot_j2s6s300_link_finger_tip_3_visual'>
          <pose>0 0 0 0 -0 0</pose>
          <geometry>
            <mesh>
              <scale>1 1 1</scale>
              <uri>/home/miquel/robot_sim_propio_ws/src/kinova_description/meshes/finger_distal.dae</uri>
            </mesh>
          </geometry>
        </visual>
        <self_collide>0</self_collide>
        <enable_wind>0</enable_wind>
        <kinematic>0</kinematic>
      </link>
      <joint name='robot_back_left_wheel_joint' type='revolute'>
        <pose relative_to='robot_base_footprint'>-0.229 0.235 0.11 0 -0 0</pose>
        <parent>robot_base_footprint</parent>
        <child>robot_back_left_wheel</child>
        <axis>
          <xyz>0 1 0</xyz>
          <limit>
            <effort>100</effort>
            <velocity>100</velocity>
            <lower>-1e+16</lower>
            <upper>1e+16</upper>
          </limit>
          <dynamics>
            <spring_reference>0</spring_reference>
            <spring_stiffness>0</spring_stiffness>
          </dynamics>
        </axis>
      </joint>
      <link name='robot_back_left_wheel'>
        <pose relative_to='robot_back_left_wheel_joint'>0 0 0 0 -0 0</pose>
        <inertial>
          <pose>0 0 0 0 -0 0</pose>
          <mass>6.5</mass>
          <inertia>
            <ixx>0.03185</ixx>
            <ixy>0</ixy>
            <ixz>0</ixz>
            <iyy>0.039325</iyy>
            <iyz>0</iyz>
            <izz>0.03185</izz>
          </inertia>
        </inertial>
        <collision name='robot_back_left_wheel_collision'>
          <pose>0 0 0 1.5708 -0 0</pose>
          <geometry>
            <cylinder>
              <length>0.15</length>
              <radius>0.11</radius>
            </cylinder>
          </geometry>
          <surface>
            <contact>
              <ode>
                <kp>1e+07</kp>
                <kd>1</kd>
              </ode>
            </contact>
            <friction>
              <ode>
                <mu>1</mu>
                <mu2>1</mu2>
                <fdir1>1 0 0</fdir1>
              </ode>
              <torsional>
                <ode/>
              </torsional>
            </friction>
            <bounce/>
          </surface>
          <max_contacts>10</max_contacts>
        </collision>
        <visual name='robot_back_left_wheel_visual'>
          <pose>0 0 0 0 -0 0</pose>
          <geometry>
            <mesh>
              <scale>1 1 1</scale>
              <uri>/home/miquel/robot_sim_propio_ws/src/summit_xl_description/meshes/wheels/rubber_wheel_left.dae</uri>
            </mesh>
          </geometry>
        </visual>
        <gravity>1</gravity>
        <self_collide>0</self_collide>
        <enable_wind>0</enable_wind>
        <kinematic>0</kinematic>
      </link>
      <joint name='robot_back_right_wheel_joint' type='revolute'>
        <pose relative_to='robot_base_footprint'>-0.229 -0.235 0.11 0 -0 0</pose>
        <parent>robot_base_footprint</parent>
        <child>robot_back_right_wheel</child>
        <axis>
          <xyz>0 1 0</xyz>
          <limit>
            <effort>100</effort>
            <velocity>100</velocity>
            <lower>-1e+16</lower>
            <upper>1e+16</upper>
          </limit>
          <dynamics>
            <spring_reference>0</spring_reference>
            <spring_stiffness>0</spring_stiffness>
          </dynamics>
        </axis>
      </joint>
      <link name='robot_back_right_wheel'>
        <pose relative_to='robot_back_right_wheel_joint'>0 0 0 0 -0 0</pose>
        <inertial>
          <pose>0 0 0 0 -0 0</pose>
          <mass>6.5</mass>
          <inertia>
            <ixx>0.03185</ixx>
            <ixy>0</ixy>
            <ixz>0</ixz>
            <iyy>0.039325</iyy>
            <iyz>0</iyz>
            <izz>0.03185</izz>
          </inertia>
        </inertial>
        <collision name='robot_back_right_wheel_collision'>
          <pose>0 0 0 1.5708 -0 0</pose>
          <geometry>
            <cylinder>
              <length>0.15</length>
              <radius>0.11</radius>
            </cylinder>
          </geometry>
          <surface>
            <contact>
              <ode>
                <kp>1e+07</kp>
                <kd>1</kd>
              </ode>
            </contact>
            <friction>
              <ode>
                <mu>1</mu>
                <mu2>1</mu2>
                <fdir1>1 0 0</fdir1>
              </ode>
              <torsional>
                <ode/>
              </torsional>
            </friction>
            <bounce/>
          </surface>
          <max_contacts>10</max_contacts>
        </collision>
        <visual name='robot_back_right_wheel_visual'>
          <pose>0 0 0 0 -0 0</pose>
          <geometry>
            <mesh>
              <scale>1 1 1</scale>
              <uri>/home/miquel/robot_sim_propio_ws/src/summit_xl_description/meshes/wheels/rubber_wheel_right.dae</uri>
            </mesh>
          </geometry>
        </visual>
        <gravity>1</gravity>
        <self_collide>0</self_collide>
        <enable_wind>0</enable_wind>
        <kinematic>0</kinematic>
      </link>
      <joint name='robot_front_left_wheel_joint' type='revolute'>
        <pose relative_to='robot_base_footprint'>0.229 0.235 0.11 0 -0 0</pose>
        <parent>robot_base_footprint</parent>
        <child>robot_front_left_wheel</child>
        <axis>
          <xyz>0 1 0</xyz>
          <limit>
            <effort>100</effort>
            <velocity>100</velocity>
            <lower>-1e+16</lower>
            <upper>1e+16</upper>
          </limit>
          <dynamics>
            <spring_reference>0</spring_reference>
            <spring_stiffness>0</spring_stiffness>
          </dynamics>
        </axis>
      </joint>
      <link name='robot_front_left_wheel'>
        <pose relative_to='robot_front_left_wheel_joint'>0 0 0 0 -0 0</pose>
        <inertial>
          <pose>0 0 0 0 -0 0</pose>
          <mass>6.5</mass>
          <inertia>
            <ixx>0.03185</ixx>
            <ixy>0</ixy>
            <ixz>0</ixz>
            <iyy>0.039325</iyy>
            <iyz>0</iyz>
            <izz>0.03185</izz>
          </inertia>
        </inertial>
        <collision name='robot_front_left_wheel_collision'>
          <pose>0 0 0 1.5708 -0 0</pose>
          <geometry>
            <cylinder>
              <length>0.15</length>
              <radius>0.11</radius>
            </cylinder>
          </geometry>
          <surface>
            <contact>
              <ode>
                <kp>1e+07</kp>
                <kd>1</kd>
              </ode>
            </contact>
            <friction>
              <ode>
                <mu>1</mu>
                <mu2>1</mu2>
                <fdir1>1 0 0</fdir1>
              </ode>
              <torsional>
                <ode/>
              </torsional>
            </friction>
            <bounce/>
          </surface>
          <max_contacts>10</max_contacts>
        </collision>
        <visual name='robot_front_left_wheel_visual'>
          <pose>0 0 0 0 -0 0</pose>
          <geometry>
            <mesh>
              <scale>1 1 1</scale>
              <uri>/home/miquel/robot_sim_propio_ws/src/summit_xl_description/meshes/wheels/rubber_wheel_left.dae</uri>
            </mesh>
          </geometry>
        </visual>
        <gravity>1</gravity>
        <self_collide>0</self_collide>
        <enable_wind>0</enable_wind>
        <kinematic>0</kinematic>
      </link>
      <joint name='robot_front_right_wheel_joint' type='revolute'>
        <pose relative_to='robot_base_footprint'>0.229 -0.235 0.11 0 -0 0</pose>
        <parent>robot_base_footprint</parent>
        <child>robot_front_right_wheel</child>
        <axis>
          <xyz>0 1 0</xyz>
          <limit>
            <effort>100</effort>
            <velocity>100</velocity>
            <lower>-1e+16</lower>
            <upper>1e+16</upper>
          </limit>
          <dynamics>
            <spring_reference>0</spring_reference>
            <spring_stiffness>0</spring_stiffness>
          </dynamics>
        </axis>
      </joint>
      <link name='robot_front_right_wheel'>
        <pose relative_to='robot_front_right_wheel_joint'>0 0 0 0 -0 0</pose>
        <inertial>
          <pose>0 0 0 0 -0 0</pose>
          <mass>6.5</mass>
          <inertia>
            <ixx>0.03185</ixx>
            <ixy>0</ixy>
            <ixz>0</ixz>
            <iyy>0.039325</iyy>
            <iyz>0</iyz>
            <izz>0.03185</izz>
          </inertia>
        </inertial>
        <collision name='robot_front_right_wheel_collision'>
          <pose>0 0 0 1.5708 -0 0</pose>
          <geometry>
            <cylinder>
              <length>0.15</length>
              <radius>0.11</radius>
            </cylinder>
          </geometry>
          <surface>
            <contact>
              <ode>
                <kp>1e+07</kp>
                <kd>1</kd>
              </ode>
            </contact>
            <friction>
              <ode>
                <mu>1</mu>
                <mu2>1</mu2>
                <fdir1>1 0 0</fdir1>
              </ode>
              <torsional>
                <ode/>
              </torsional>
            </friction>
            <bounce/>
          </surface>
          <max_contacts>10</max_contacts>
        </collision>
        <visual name='robot_front_right_wheel_visual'>
          <pose>0 0 0 0 -0 0</pose>
          <geometry>
            <mesh>
              <scale>1 1 1</scale>
              <uri>/home/miquel/robot_sim_propio_ws/src/summit_xl_description/meshes/wheels/rubber_wheel_right.dae</uri>
            </mesh>
          </geometry>
        </visual>
        <gravity>1</gravity>
        <self_collide>0</self_collide>
        <enable_wind>0</enable_wind>
        <kinematic>0</kinematic>
      </link>
      <plugin name='ros_control' filename='libgazebo_ros_control.so'>
        <robotParam>robot_description</robotParam>
        <controlPeriod>0.001</controlPeriod>
        <robotSimType>gazebo_ros_control/DefaultRobotHWSim</robotSimType>
        <legacyModeNS>1</legacyModeNS>
        <robotNamespace>/</robotNamespace>
      </plugin>
      <plugin name='ft_sensor' filename='libgazebo_ros_ft_sensor.so'>
        <updateRate>30.0</updateRate>
        <topicName>robot_j2s6s300_joint_1_ft_sensor_topic</topicName>
        <jointName>robot_j2s6s300_joint_1</jointName>
        <robotNamespace>/</robotNamespace>
      </plugin>
      <plugin name='ft_sensor' filename='libgazebo_ros_ft_sensor.so'>
        <updateRate>30.0</updateRate>
        <topicName>robot_j2s6s300_joint_2_ft_sensor_topic</topicName>
        <jointName>robot_j2s6s300_joint_2</jointName>
        <robotNamespace>/</robotNamespace>
      </plugin>
      <plugin name='ft_sensor' filename='libgazebo_ros_ft_sensor.so'>
        <updateRate>30.0</updateRate>
        <topicName>robot_j2s6s300_joint_3_ft_sensor_topic</topicName>
        <jointName>robot_j2s6s300_joint_3</jointName>
        <robotNamespace>/</robotNamespace>
      </plugin>
      <plugin name='ft_sensor' filename='libgazebo_ros_ft_sensor.so'>
        <updateRate>30.0</updateRate>
        <topicName>robot_j2s6s300_joint_4_ft_sensor_topic</topicName>
        <jointName>robot_j2s6s300_joint_4</jointName>
        <robotNamespace>/</robotNamespace>
      </plugin>
      <plugin name='ft_sensor' filename='libgazebo_ros_ft_sensor.so'>
        <updateRate>30.0</updateRate>
        <topicName>robot_j2s6s300_joint_5_ft_sensor_topic</topicName>
        <jointName>robot_j2s6s300_joint_5</jointName>
        <robotNamespace>/</robotNamespace>
      </plugin>
      <static>0</static>
      <plugin name='ft_sensor' filename='libgazebo_ros_ft_sensor.so'>
        <updateRate>30.0</updateRate>
        <topicName>robot_j2s6s300_joint_6_ft_sensor_topic</topicName>
        <jointName>robot_j2s6s300_joint_6</jointName>
        <robotNamespace>/</robotNamespace>
      </plugin>
      <pose>0 0 0 0 -0 0</pose>
    </model>
    <state world_name='default'>
      <sim_time>34 950000000</sim_time>
      <real_time>35 472464520</real_time>
      <wall_time>1715934818 474372730</wall_time>
      <iterations>34950</iterations>
      <model name='ground_plane'>
        <pose>0 0 0 0 -0 0</pose>
        <scale>1 1 1</scale>
        <link name='link'>
          <pose>0 0 0 0 -0 0</pose>
          <velocity>0 0 0 0 -0 0</velocity>
          <acceleration>0 0 0 0 -0 0</acceleration>
          <wrench>0 0 0 0 -0 0</wrench>
        </link>
      </model>
      <model name='robot'>
        <pose>0.001605 0.000145 -0 0 -1.6e-05 -0.000215</pose>
        <scale>1 1 1</scale>
        <link name='robot_back_left_wheel'>
          <pose>-0.227347 0.235195 0.109996 -0 -0.005287 -0.000215</pose>
          <velocity>-0.002407 -2.3e-05 -0.002804 0.00021 -0.022013 -4e-06</velocity>
          <acceleration>-1.46997 0.012954 -4.74126 3.02493 0.844115 -3.05605</acceleration>
          <wrench>-9.55483 0.084202 -30.8182 0 -0 0</wrench>
        </link>
        <link name='robot_back_right_wheel'>
          <pose>-0.227447 -0.234805 0.109996 0 -0.003972 -0.000215</pose>
          <velocity>-0.002461 -2.4e-05 -0.002876 0.000214 -0.022474 1e-06</velocity>
          <acceleration>-1.44058 0.011485 -4.5599 3.03816 1.29536 -3.04605</acceleration>
          <wrench>-9.36375 0.074651 -29.6394 0 -0 0</wrench>
        </link>
        <link name='robot_base_footprint'>
          <pose>0.001605 0.000145 -0 0 -1.6e-05 -0.000215</pose>
          <velocity>-9.3e-05 -4.6e-05 0.00211 0.000153 -0.021631 -0.000163</velocity>
          <acceleration>-1.53903 0.006263 -2.34215 2.77418 0.47344 -3.13216</acceleration>
          <wrench>-39.3143 0.159978 -59.8297 0 -0 0</wrench>
        </link>
        <link name='robot_front_left_wheel'>
          <pose>0.230653 0.235096 0.110003 0 0.01662 -0.000215</pose>
          <velocity>-0.002419 -0.000104 0.007098 8.8e-05 -0.021627 -0.000176</velocity>
          <acceleration>-1.47862 -0.013109 -0.214675 2.40187 0.489761 3.13838</acceleration>
          <wrench>-9.61105 -0.085207 -1.39539 0 -0 0</wrench>
        </link>
        <link name='robot_front_right_wheel'>
          <pose>0.230552 -0.234904 0.110003 0 0.016002 -0.000215</pose>
          <velocity>-0.002499 -0.000101 0.007025 0.000145 -0.021628 -0.000168</velocity>
          <acceleration>-1.42563 -0.008486 -0.038394 2.44555 1.41166 3.01289</acceleration>
          <wrench>-9.26657 -0.05516 -0.249564 0 -0 0</wrench>
        </link>
        <link name='robot_j2s6s300_link_1'>
          <pose>0.205599 0.000102 0.376753 -3.14159 1.6e-05 3.14145</pose>
          <velocity>-0.008395 -0.000134 0.006512 0.000957 -0.022319 0.01403</velocity>
          <acceleration>-4.93381 -0.170097 -0.387658 2.08986 1.32367 -0.239999</acceleration>
          <wrench>-3.68901 -0.127182 -0.289852 0 -0 0</wrench>
        </link>
        <link name='robot_j2s6s300_link_2'>
          <pose>0.205597 0.001701 0.495503 -1.57076 -1.19585 3.14141</pose>
          <velocity>-0.010927 -0.000166 0.006586 0.002247 0.901943 0.014569</velocity>
          <acceleration>22.4563 1.53061 -71.7783 0.771267 0.669674 0.942701</acceleration>
          <wrench>22.2317 1.5153 -71.0605 0 -0 0</wrench>
        </link>
        <link name='robot_j2s6s300_link_3'>
          <pose>0.587113 0.001647 0.645654 1.57082 -0.269147 3.14144</pose>
          <velocity>0.124584 0.005054 -0.337411 0.002714 -0.721881 0.014808</velocity>
          <acceleration>30.9024 1.82286 -137.101 -1.16355 -0.018613 -0.101089</acceleration>
          <wrench>20.8993 1.2328 -92.7215 0 -0 0</wrench>
        </link>
        <link name='robot_j2s6s300_link_4'>
          <pose>0.642235 -0.009757 0.845492 -3.14157 0.269144 1.2e-05</pose>
          <velocity>-0.019548 0.005356 -0.297587 -0.011505 -0.721642 -0.036149</velocity>
          <acceleration>-12.4969 -0.456765 -125.272 1.44755 0.730401 -2.51144</acceleration>
          <wrench>-5.78607 -0.211482 -58.001 0 -0 0</wrench>
        </link>
        <link name='robot_j2s6s300_link_5'>
          <pose>0.669823 -0.009758 0.945507 -1.57098 1.48924 3.14142</pose>
          <velocity>-0.091587 0.005505 -0.277712 3.13029 -1.30438 3.10566</velocity>
          <acceleration>-21.5795 -0.940043 -87.1255 2.97596 -0.938667 2.20925</acceleration>
          <wrench>-9.99129 -0.43524 -40.3391 0 -0 0</wrench>
        </link>
        <link name='robot_j2s6s300_link_6'>
          <pose>0.773228 -0.009757 0.937055 0.001884 -1.48923 -0.001884</pose>
          <velocity>-0.075731 0.001749 -0.087854 -2.68865 -1.30262 3.06664</velocity>
          <acceleration>-15.0215 -0.555836 -7.10967 -2.10696 0.814495 -1.1389</acceleration>
          <wrench>-14.8713 -0.550278 -7.03857 0 -0 0</wrench>
        </link>
        <link name='robot_j2s6s300_link_finger_1'>
          <pose>0.887751 0.021513 0.930491 -2.9215 -0.053371 0.598149</pose>
          <velocity>-0.056488 -0.010348 0.137899 0.187812 -1.20077 2.99653</velocity>
          <acceleration>-13.0945 -7.8181 52.5492 2.84899 -1.43487 1.4788</acceleration>
          <wrench>-0.130945 -0.078181 0.525492 0 -0 0</wrench>
        </link>
        <link name='robot_j2s6s300_link_finger_2'>
          <pose>0.889481 -0.036843 0.949878 -0.198455 0.036094 -0.234639</pose>
          <velocity>-0.100967 -0.009705 0.114545 0.758535 -1.22906 -2.9182</velocity>
          <acceleration>-25.8838 13.1192 51.8306 1.89579 -1.23693 2.63265</acceleration>
          <wrench>-0.258838 0.131192 0.518306 0 -0 0</wrench>
        </link>
        <link name='robot_j2s6s300_link_finger_3'>
          <pose>0.885853 -0.036815 0.905504 0.160716 0.122637 -0.234409</pose>
          <velocity>-0.019461 0.005428 0.108182 -2.65247 -1.20747 -2.96998</velocity>
          <acceleration>11.6205 13.5187 54.7084 -0.881868 0.269622 1.9581</acceleration>
          <wrench>0.116205 0.135187 0.547084 0 -0 0</wrench>
        </link>
        <link name='robot_j2s6s300_link_finger_tip_1'>
          <pose>0.922382 0.048666 0.933494 -2.96203 0.1385 -0.28661</pose>
          <velocity>0.029834 -0.127483 0.18435 -2.72927 -1.40006 2.4861</velocity>
          <acceleration>-15.7237 -12.4908 83.4928 1.85891 -0.756748 1.47254</acceleration>
          <wrench>-0.157237 -0.124908 0.834928 0 -0 0</wrench>
        </link>
        <link name='robot_j2s6s300_link_finger_tip_2'>
          <pose>0.931581 -0.049938 0.94888 -0.046019 0.196347 0.926947</pose>
          <velocity>-0.053755 0.135106 0.155939 3.03759 -0.022349 2.65431</velocity>
          <acceleration>0.293389 7.66899 79.4764 1.96691 0.213386 -2.09326</acceleration>
          <wrench>0.002934 0.07669 0.794764 0 -0 0</wrench>
        </link>
        <link name='robot_j2s6s300_link_finger_tip_3'>
          <pose>0.927583 -0.049817 0.899646 0.193346 -0.058372 0.701167</pose>
          <velocity>-0.005684 0.01324 0.182376 -2.77363 -1.46576 2.03539</velocity>
          <acceleration>37.1564 8.51928 83.0387 -0.521416 -0.893953 0.765425</acceleration>
          <wrench>0.371564 0.085193 0.830387 0 -0 0</wrench>
        </link>
      </model>
      <model name='table_model'>
        <pose>-0.000305 -4e-06 -0.498792 -1e-06 0.000483 3e-06</pose>
        <scale>1 1 1</scale>
        <link name='my_table'>
          <pose>-0.000305 -4e-06 -0.498792 -1e-06 0.000483 3e-06</pose>
          <velocity>0 0 0 0 -0 0</velocity>
          <acceleration>-0.159548 2.27802 4.03689 -0.503419 -0.069973 1.22039</acceleration>
          <wrench>-0.159548 2.27802 4.03689 0 -0 0</wrench>
        </link>
      </model>
      <light name='sun'>
        <pose>0 0 10 0 -0 0</pose>
      </light>
    </state>
    <gui fullscreen='0'>
      <camera name='user_camera'>
        <pose>5.37184 -4.66373 1.91107 0 0.275643 2.35619</pose>
        <view_controller>orbit</view_controller>
        <projection_type>perspective</projection_type>
      </camera>
    </gui>
  </world>
</sdf>
